Workbook

Sheet Dados
A1: PLANILHA DE APOIO - VIGA CONTÍNUA PROTENDIDA (2 × 10 m)
A2: Células amarelas = dados de entrada. Todas as demais abas são recalculadas a partir desta aba. Unidades: kN, m, MPa (salvo indicação).
A4: 1. Geometria e materiais
A5: L | B5: Vão de cada tramo | C5: 10 | D5: m | E5: viga contínua de 2 vãos iguais
A6: bw | B6: Largura da seção | C6: 0.3 | D6: m
A7: h | B7: Altura da seção | C7: 0.9 | D7: m
A8: Ac | B8: Área Ac | C8: =$C$6*$C$7 | D8: m²
A9: Ic | B9: Inércia Ic | C9: =$C$6*$C$7^3/12 | D9: m⁴
A10: W | B10: Módulo resistente W1 = W2 | C10: =$C$9/($C$7/2) | D10: m³
A11: k | B11: Núcleo central k = W/Ac | C11: =$C$10/$C$8 | D11: m
A12: fck | B12: fck | C12: 30 | D12: MPa
A13: gc | B13: γc | C13: 1.4
A14: fcd | B14: fcd | C14: =$C$12/$C$13 | D14: MPa
A15: fctm | B15: fct,m = 0,3·fck^(2/3) | C15: =0.3*$C$12^(2/3) | D15: MPa
A16: fctkinf | B16: fctk,inf = 0,7·fct,m | C16: =0.7*$C$15 | D16: MPa
A17: fctd | B17: fctd = fctk,inf/γc | C17: =$C$16/$C$13 | D17: MPa
A18: Eci | B18: Eci = 5600·√fck | C18: =5600*SQRT($C$12) | D18: MPa
A19: ai | B19: αi = 0,8+0,2·fck/80 ≤ 1 | C19: =MIN(0.8+0.2*$C$12/80,1)
A20: Ecs | B20: Ecs = αi·Eci | C20: =$C$19*$C$18 | D20: MPa
A21: t0 | B21: Idade da protensão (ato) | C21: 7 | D21: dias
A22: fcj | B22: fcj = exp[0,38(1-√(28/t))]·fck | C22: =EXP(0.38*(1-SQRT(28/$C$21)))*$C$12 | D22: MPa
A23: Ecij | B23: Eci,j = 5600·√fcj | C23: =5600*SQRT($C$22) | D23: MPa
A24: fctmj | B24: fct,m,j | C24: =0.3*$C$22^(2/3) | D24: MPa
A25: ft_els | B25: Limite de tração ELS-F: 1,2·fctk,inf | C25: =1.2*$C$16 | D25: MPa
A26: ft_ato | B26: Limite de tração no ato: 1,2·fct,m,j | C26: =1.2*$C$24 | D26: MPa
A27: fc_ato | B27: Limite de compressão no ato: 0,7·fcj | C27: =0.7*$C$22 | D27: MPa
A28: fc_els | B28: Limite de compressão em serviço: 0,7·fck | C28: =0.7*$C$12 | D28: MPa
A29: 2. Ações
A30: gpp | B30: Peso próprio g0 = 25·Ac | C30: =25*$C$8 | D30: kN/m
A31: gadd | B31: Carga permanente adicional (tabuleiro, piso, guarda-corpo) | C31: 13.25 | D31: kN/m | E31: ADOTADO - provisório (confirmar com a biapoiada)
A32: g | B32: Carga permanente total g | C32: =$C$30+$C$31 | D32: kN/m
A33: q | B33: Sobrecarga q (passarela) | C33: 25 | D33: kN/m | E33: ADOTADO - provisório (5 kN/m² × 5 m)
A34: psi1 | B34: ψ1 (passarela, NBR 8681) | C34: 0.4
A35: psi2 | B35: ψ2 (passarela, NBR 8681) | C35: 0.3
A36: pbal | B36: a) Carga a equilibrar = g + ψ2·q | C36: =$C$32+$C$35*$C$33 | D36: kN/m
A37: 3. Cobrimento, excentricidades e traçado do cabo resultante
A38: cnom | B38: Cobrimento nominal (CAA II, protendido) | C38: 0.035 | D38: m
A39: phit | B39: Estribo Ø | C39: 0.01 | D39: m
A40: dbain | B40: Bainha: diâmetro externo (5 Ø12,7) | C40: 0.061 | D40: m
A41: dpp | B41: d' = c + Øestribo + Øbainha/2 | C41: =$C$38+$C$39+$C$40/2 | D41: m
...

Sheet Esforcos
A1: Esforços externos - viga contínua de 2 vãos iguais (envoltórias)
A2: Momento positivo = tração embaixo. Padrões de sobrecarga: ambos os vãos, só o vão do ponto, só o outro vão. Estações a cada 0,5 m (0 a 20 m).
A6: i | B6: x | C6: s (espelho) | D6: Mg0 (g0) | E6: Mg (g) | F6: Mq,máx | G6: Mq,mín | H6: M CFQ,máx = Mg+ψ1Mq+ | I6: M CFQ,mín = Mg+ψ1Mq- | J6: M CR,máx = Mg+Mq+ | K6: M CR,mín = Mg+Mq- | L6: Vg | M6: Vq,máx | N6: Vq,mín
B7: m | C7: m | D7: kN·m | E7: kN·m | F7: kN·m | G7: kN·m | H7: kN·m | I7: kN·m | J7: kN·m | K7: kN·m | L7: kN | M7: kN | N7: kN
A8: 0 | B8: =A8*0.5 | C8: =IF(B8<=Dados!$C$5,B8,2*Dados!$C$5-B8) | D8: =(3*Dados!$C$30*Dados!$C$5*C8/8-Dados!$C$30*C8^2/2) | E8: =(3*Dados!$C$32*Dados!$C$5*C8/8-Dados!$C$32*C8^2/2) | F8: =MAX(0,(3*Dados!$C$33*Dados!$C$5*C8/8-Dados!$C$33*C8^2/2),(7*Dados!$C$33*Dados!$C$5*C8/16-Dados!$C$33*C8^2/2),(-Dados!$C$33*Dados!$C$5*C8/16)) | G8: =MIN(0,(3*Dados!$C$33*Dados!$C$5*C8/8-Dados!$C$33*C8^2/2),(7*Dados!$C$33*Dados!$C$5*C8/16-Dados!$C$33*C8^2/2),(-Dados!$C$33*Dados!$C$5*C8/16)) | H8: =E8+Dados!$C$34*F8 | I8: =E8+Dados!$C$34*G8 | J8: =E8+F8 | K8: =E8+G8 | L8: =IF(B8<=Dados!$C$5,1,-1)*(3*Dados!$C$32*Dados!$C$5/8-Dados!$C$32*C8) | M8: =IF(B8<=Dados!$C$5,MAX(0,(3*Dados!$C$33*Dados!$C$5/8-Dados!$C$33*C8),(7*Dados!$C$33*Dados!$C$5/16-Dados!$C$33*C8),(-Dados!$C$33*Dados!$C$5/16)),-MIN(0,(3*Dados!$C$33*Dados!$C$5/8-Dados!$C$33*C8),(7*Dados!$C$33*Dados!$C$5/16-Dados!$C$33*C8),(-Dados!$C$33*Dados!$C$5/16))) | N8: =IF(B8<=Dados!$C$5,MIN(0,(3*Dados!$C$33*Dados!$C$5/8-Dados!$C$33*C8),(7*Dados!$C$33*Dados!$C$5/16-Dados!$C$33*C8),(-Dados!$C$33*Dados!$C$5/16)),-MAX(0,(3*Dados!$C$33*Dados!$C$5/8-Dados!$C$33*C8),(7*Dados!$C$33*Dados!$C$5/16-Dados!$C$33*C8),(-Dados!$C$33*Dados!$C$5/16)))
A9: 1 | B9: =A9*0.5 | C9: =IF(B9<=Dados!$C$5,B9,2*Dados!$C$5-B9) | D9: =(3*Dados!$C$30*Dados!$C$5*C9/8-Dados!$C$30*C9^2/2) | E9: =(3*Dados!$C$32*Dados!$C$5*C9/8-Dados!$C$32*C9^2/2) | F9: =MAX(0,(3*Dados!$C$33*Dados!$C$5*C9/8-Dados!$C$33*C9^2/2),(7*Dados!$C$33*Dados!$C$5*C9/16-Dados!$C$33*C9^2/2),(-Dados!$C$33*Dados!$C$5*C9/16)) | G9: =MIN(0,(3*Dados!$C$33*Dados!$C$5*C9/8-Dados!$C$33*C9^2/2),(7*Dados!$C$33*Dados!$C$5*C9/16-Dados!$C$33*C9^2/2),(-Dados!$C$33*Dados!$C$5*C9/16)) | H9: =E9+Dados!$C$34*F9 | I9: =E9+Dados!$C$34*G9 | J9: =E9+F9 | K9: =E9+G9 | L9: =IF(B9<=Dados!$C$5,1,-1)*(3*Dados!$C$32*Dados!$C$5/8-Dados!$C$32*C9) | M9: =IF(B9<=Dados!$C$5,MAX(0,(3*Dados!$C$33*Dados!$C$5/8-Dados!$C$33*C9),(7*Dados!$C$33*Dados!$C$5/16-Dados!$C$33*C9),(-Dados!$C$33*Dados!$C$5/16)),-MIN(0,(3*Dados!$C$33*Dados!$C$5/8-Dados!$C$33*C9),(7*Dados!$C$33*Dados!$C$5/16-Dados!$C$33*C9),(-Dados!$C$33*Dados!$C$5/16))) | N9: =IF(B9<=Dados!$C$5,MIN(0,(3*Dados!$C$33*Dados!$C$5/8-Dados!$C$33*C9),(7*Dados!$C$33*Dados!$C$5/16-Dados!$C$33*C9),(-Dados!$C$33*Dados!$C$5/16)),-MAX(0,(3*Dados!$C$33*Dados!$C$5/8-Dados!$C$33*C9),(7*Dados!$C$33*Dados!$C$5/16-Dados!$C$33*C9),(-Dados!$C$33*Dados!$C$5/16)))
A10: 2 | B10: =A10*0.5 | C10: =IF(B10<=Dados!$C$5,B10,2*Dados!$C$5-B10) | D10: =(3*Dados!$C$30*Dados!$C$5*C10/8-Dados!$C$30*C10^2/2) | E10: =(3*Dados!$C$32*Dados!$C$5*C10/8-Dados!$C$32*C10^2/2) | F10: =MAX(0,(3*Dados!$C$33*Dados!$C$5*C10/8-Dados!$C$33*C10^2/2),(7*Dados!$C$33*Dados!$C$5*C10/16-Dados!$C$33*C10^2/2),(-Dados!$C$33*Dados!$C$5*C10/16)) | G10: =MIN(0,(3*Dados!$C$33*Dados!$C$5*C10/8-Dados!$C$33*C10^2/2),(7*Dados!$C$33*Dados!$C$5*C10/16-Dados!$C$33*C10^2/2),(-Dados!$C$33*Dados!$C$5*C10/16)) | H10: =E10+Dados!$C$34*F10 | I10: =E10+Dados!$C$34*G10 | J10: =E10+F10 | K10: =E10+G10 | L10: =IF(B10<=Dados!$C$5,1,-1)*(3*Dados!$C$32*Dados!$C$5/8-Dados!$C$32*C10) | M10: =IF(B10<=Dados!$C$5,MAX(0,(3*Dados!$C$33*Dados!$C$5/8-Dados!$C$33*C10),(7*Dados!$C$33*Dados!$C$5/16-Dados!$C$33*C10),(-Dados!$C$33*Dados!$C$5/16)),-MIN(0,(3*Dados!$C$33*Dados!$C$5/8-Dados!$C$33*C10),(7*Dados!$C$33*Dados!$C$5/16-Dados!$C$33*C10),(-Dados!$C$33*Dados!$C$5/16))) | N10: =IF(B10<=Dados!$C$5,MIN(0,(3*Dados!$C$33*Dados!$C$5/8-Dados!$C$33*C10),(7*Dados!$C$33*Dados!$C$5/16-Dados!$C$33*C10),(-Dados!$C$33*Dados!$C$5/16)),-MAX(0,(3*Dados!$C$33*Dados!$C$5/8-Dados!$C$33*C10),(7*Dados!$C$33*Dados!$C$5/16-Dados!$C$33*C10),(-Dados!$C$33*Dados!$C$5/16)))
A11: 3 | B11: =A11*0.5 | C11: =IF(B11<=Dados!$C$5,B11,2*Dados!$C$5-B11) | D11: =(3*Dados!$C$30*Dados!$C$5*C11/8-Dados!$C$30*C11^2/2) | E11: =(3*Dados!$C$32*Dados!$C$5*C11/8-Dados!$C$32*C11^2/2) | F11: =MAX(0,(3*Dados!$C$33*Dados!$C$5*C11/8-Dados!$C$33*C11^2/2),(7*Dados!$C$33*Dados!$C$5*C11/16-Dados!$C$33*C11^2/2),(-Dados!$C$33*Dados!$C$5*C11/16)) | G11: =MIN(0,(3*Dados!$C$33*Dados!$C$5*C11/8-Dados!$C$33*C11^2/2),(7*Dados!$C$33*Dados!$C$5*C11/16-Dados!$C$33*C11^2/2),(-Dados!$C$33*Dados!$C$5*C11/16)) | H11: =E11+Dados!$C$34*F11 | I11: =E11+Dados!$C$34*G11 | J11: =E11+F11 | K11: =E11+G11 | L11: =IF(B11<=Dados!$C$5,1,-1)*(3*Dados!$C$32*Dados!$C$5/8-Dados!$C$32*C11) | M11: =IF(B11<=Dados!$C$5,MAX(0,(3*Dados!$C$33*Dados!$C$5/8-Dados!$C$33*C11),(7*Dados!$C$33*Dados!$C$5/16-Dados!$C$33*C11),(-Dados!$C$33*Dados!$C$5/16)),-MIN(0,(3*Dados!$C$33*Dados!$C$5/8-Dados!$C$33*C11),(7*Dados!$C$33*Dados!$C$5/16-Dados!$C$33*C11),(-Dados!$C$33*Dados!$C$5/16))) | N11: =IF(B11<=Dados!$C$5,MIN(0,(3*Dados!$C$33*Dados!$C$5/8-Dados!$C$33*C11),(7*Dados!$C$33*Dados!$C$5/16-Dados!$C$33*C11),(-Dados!$C$33*Dados!$C$5/16)),-MAX(0,(3*Dados!$C$33*Dados!$C$5/8-Dados!$C$33*C11),(7*Dados!$C$33*Dados!$C$5/16-Dados!$C$33*C11),(-Dados!$C$33*Dados!$C$5/16)))
A12: 4 | B12: =A12*0.5 | C12: =IF(B12<=Dados!$C$5,B12,2*Dados!$C$5-B12) | D12: =(3*Dados!$C$30*Dados!$C$5*C12/8-Dados!$C$30*C12^2/2) | E12: =(3*Dados!$C$32*Dados!$C$5*C12/8-Dados!$C$32*C12^2/2) | F12: =MAX(0,(3*Dados!$C$33*Dados!$C$5*C12/8-Dados!$C$33*C12^2/2),(7*Dados!$C$33*Dados!$C$5*C12/16-Dados!$C$33*C12^2/2),(-Dados!$C$33*Dados!$C$5*C12/16)) | G12: =MIN(0,(3*Dados!$C$33*Dados!$C$5*C12/8-Dados!$C$33*C12^2/2),(7*Dados!$C$33*Dados!$C$5*C12/16-Dados!$C$33*C12^2/2),(-Dados!$C$33*Dados!$C$5*C12/16)) | H12: =E12+Dados!$C$34*F12 | I12: =E12+Dados!$C$34*G12 | J12: =E12+F12 | K12: =E12+G12 | L12: =IF(B12<=Dados!$C$5,1,-1)*(3*Dados!$C$32*Dados!$C$5/8-Dados!$C$32*C12) | M12: =IF(B12<=Dados!$C$5,MAX(0,(3*Dados!$C$33*Dados!$C$5/8-Dados!$C$33*C12),(7*Dados!$C$33*Dados!$C$5/16-Dados!$C$33*C12),(-Dados!$C$33*Dados!$C$5/16)),-MIN(0,(3*Dados!$C$33*Dados!$C$5/8-Dados!$C$33*C12),(7*Dados!$C$33*Dados!$C$5/16-Dados!$C$33*C12),(-Dados!$C$33*Dados!$C$5/16))) | N12: =IF(B12<=Dados!$C$5,MIN(0,(3*Dados!$C$33*Dados!$C$5/8-Dados!$C$33*C12),(7*Dados!$C$33*Dados!$C$5/16-Dados!$C$33*C12),(-Dados!$C$33*Dados!$C$5/16)),-MAX(0,(3*Dados!$C$33*Dados!$C$5/8-Dados!$C$33*C12),(7*Dados!$C$33*Dados!$C$5/16-Dados!$C$33*C12),(-Dados!$C$33*Dados!$C$5/16)))
A13: 5 | B13: =A13*0.5 | C13: =IF(B13<=Dados!$C$5,B13,2*Dados!$C$5-B13) | D13: =(3*Dados!$C$30*Dados!$C$5*C13/8-Dados!$C$30*C13^2/2) | E13: =(3*Dados!$C$32*Dados!$C$5*C13/8-Dados!$C$32*C13^2/2) | F13: =MAX(0,(3*Dados!$C$33*Dados!$C$5*C13/8-Dados!$C$33*C13^2/2),(7*Dados!$C$33*Dados!$C$5*C13/16-Dados!$C$33*C13^2/2),(-Dados!$C$33*Dados!$C$5*C13/16)) | G13: =MIN(0,(3*Dados!$C$33*Dados!$C$5*C13/8-Dados!$C$33*C13^2/2),(7*Dados!$C$33*Dados!$C$5*C13/16-Dados!$C$33*C13^2/2),(-Dados!$C$33*Dados!$C$5*C13/16)) | H13: =E13+Dados!$C$34*F13 | I13: =E13+Dados!$C$34*G13 | J13: =E13+F13 | K13: =E13+G13 | L13: =IF(B13<=Dados!$C$5,1,-1)*(3*Dados!$C$32*Dados!$C$5/8-Dados!$C$32*C13) | M13: =IF(B13<=Dados!$C$5,MAX(0,(3*Dados!$C$33*Dados!$C$5/8-Dados!$C$33*C13),(7*Dados!$C$33*Dados!$C$5/16-Dados!$C$33*C13),(-Dados!$C$33*Dados!$C$5/16)),-MIN(0,(3*Dados!$C$33*Dados!$C$5/8-Dados!$C$33*C13),(7*Dados!$C$33*Dados!$C$5/16-Dados!$C$33*C13),(-Dados!$C$33*Dados!$C$5/16))) | N13: =IF(B13<=Dados!$C$5,MIN(0,(3*Dados!$C$33*Dados!$C$5/8-Dados!$C$33*C13),(7*Dados!$C$33*Dados!$C$5/16-Dados!$C$33*C13),(-Dados!$C$33*Dados!$C$5/16)),-MAX(0,(3*Dados!$C$33*Dados!$C$5/8-Dados!$C$33*C13),(7*Dados!$C$33*Dados!$C$5/16-Dados!$C$33*C13),(-Dados!$C$33*Dados!$C$5/16)))
A14: 6 | B14: =A14*0.5 | C14: =IF(B14<=Dados!$C$5,B14,2*Dados!$C$5-B14) | D14: =(3*Dados!$C$30*Dados!$C$5*C14/8-Dados!$C$30*C14^2/2) | E14: =(3*Dados!$C$32*Dados!$C$5*C14/8-Dados!$C$32*C14^2/2) | F14: =MAX(0,(3*Dados!$C$33*Dados!$C$5*C14/8-Dados!$C$33*C14^2/2),(7*Dados!$C$33*Dados!$C$5*C14/16-Dados!$C$33*C14^2/2),(-Dados!$C$33*Dados!$C$5*C14/16)) | G14: =MIN(0,(3*Dados!$C$33*Dados!$C$5*C14/8-Dados!$C$33*C14^2/2),(7*Dados!$C$33*Dados!$C$5*C14/16-Dados!$C$33*C14^2/2),(-Dados!$C$33*Dados!$C$5*C14/16)) | H14: =E14+Dados!$C$34*F14 | I14: =E14+Dados!$C$34*G14 | J14: =E14+F14 | K14: =E14+G14 | L14: =IF(B14<=Dados!$C$5,1,-1)*(3*Dados!$C$32*Dados!$C$5/8-Dados!$C$32*C14) | M14: =IF(B14<=Dados!$C$5,MAX(0,(3*Dados!$C$33*Dados!$C$5/8-Dados!$C$33*C14),(7*Dados!$C$33*Dados!$C$5/16-Dados!$C$33*C14),(-Dados!$C$33*Dados!$C$5/16)),-MIN(0,(3*Dados!$C$33*Dados!$C$5/8-Dados!$C$33*C14),(7*Dados!$C$33*Dados!$C$5/16-Dados!$C$33*C14),(-Dados!$C$33*Dados!$C$5/16))) | N14: =IF(B14<=Dados!$C$5,MIN(0,(3*Dados!$C$33*Dados!$C$5/8-Dados!$C$33*C14),(7*Dados!$C$33*Dados!$C$5/16-Dados!$C$33*C14),(-Dados!$C$33*Dados!$C$5/16)),-MAX(0,(3*Dados!$C$33*Dados!$C$5/8-Dados!$C$33*C14),(7*Dados!$C$33*Dados!$C$5/16-Dados!$C$33*C14),(-Dados!$C$33*Dados!$C$5/16)))
A15: 7 | B15: =A15*0.5 | C15: =IF(B15<=Dados!$C$5,B15,2*Dados!$C$5-B15) | D15: =(3*Dados!$C$30*Dados!$C$5*C15/8-Dados!$C$30*C15^2/2) | E15: =(3*Dados!$C$32*Dados!$C$5*C15/8-Dados!$C$32*C15^2/2) | F15: =MAX(0,(3*Dados!$C$33*Dados!$C$5*C15/8-Dados!$C$33*C15^2/2),(7*Dados!$C$33*Dados!$C$5*C15/16-Dados!$C$33*C15^2/2),(-Dados!$C$33*Dados!$C$5*C15/16)) | G15: =MIN(0,(3*Dados!$C$33*Dados!$C$5*C15/8-Dados!$C$33*C15^2/2),(7*Dados!$C$33*Dados!$C$5*C15/16-Dados!$C$33*C15^2/2),(-Dados!$C$33*Dados!$C$5*C15/16)) | H15: =E15+Dados!$C$34*F15 | I15: =E15+Dados!$C$34*G15 | J15: =E15+F15 | K15: =E15+G15 | L15: =IF(B15<=Dados!$C$5,1,-1)*(3*Dados!$C$32*Dados!$C$5/8-Dados!$C$32*C15) | M15: =IF(B15<=Dados!$C$5,MAX(0,(3*Dados!$C$33*Dados!$C$5/8-Dados!$C$33*C15),(7*Dados!$C$33*Dados!$C$5/16-Dados!$C$33*C15),(-Dados!$C$33*Dados!$C$5/16)),-MIN(0,(3*Dados!$C$33*Dados!$C$5/8-Dados!$C$33*C15),(7*Dados!$C$33*Dados!$C$5/16-Dados!$C$33*C15),(-Dados!$C$33*Dados!$C$5/16))) | N15: =IF(B15<=Dados!$C$5,MIN(0,(3*Dados!$C$33*Dados!$C$5/8-Dados!$C$33*C15),(7*Dados!$C$33*Dados!$C$5/16-Dados!$C$33*C15),(-Dados!$C$33*Dados!$C$5/16)),-MAX(0,(3*Dados!$C$33*Dados!$C$5/8-Dados!$C$33*C15),(7*Dados!$C$33*Dados!$C$5/16-Dados!$C$33*C15),(-Dados!$C$33*Dados!$C$5/16)))
A16: 8 | B16: =A16*0.5 | C16: =IF(B16<=Dados!$C$5,B16,2*Dados!$C$5-B16) | D16: =(3*Dados!$C$30*Dados!$C$5*C16/8-Dados!$C$30*C16^2/2) | E16: =(3*Dados!$C$32*Dados!$C$5*C16/8-Dados!$C$32*C16^2/2) | F16: =MAX(0,(3*Dados!$C$33*Dados!$C$5*C16/8-Dados!$C$33*C16^2/2),(7*Dados!$C$33*Dados!$C$5*C16/16-Dados!$C$33*C16^2/2),(-Dados!$C$33*Dados!$C$5*C16/16)) | G16: =MIN(0,(3*Dados!$C$33*Dados!$C$5*C16/8-Dados!$C$33*C16^2/2),(7*Dados!$C$33*Dados!$C$5*C16/16-Dados!$C$33*C16^2/2),(-Dados!$C$33*Dados!$C$5*C16/16)) | H16: =E16+Dados!$C$34*F16 | I16: =E16+Dados!$C$34*G16 | J16: =E16+F16 | K16: =E16+G16 | L16: =IF(B16<=Dados!$C$5,1,-1)*(3*Dados!$C$32*Dados!$C$5/8-Dados!$C$32*C16) | M16: =IF(B16<=Dados!$C$5,MAX(0,(3*Dados!$C$33*Dados!$C$5/8-Dados!$C$33*C16),(7*Dados!$C$33*Dados!$C$5/16-Dados!$C$33*C16),(-Dados!$C$33*Dados!$C$5/16)),-MIN(0,(3*Dados!$C$33*Dados!$C$5/8-Dados!$C$33*C16),(7*Dados!$C$33*Dados!$C$5/16-Dados!$C$33*C16),(-Dados!$C$33*Dados!$C$5/16))) | N16: =IF(B16<=Dados!$C$5,MIN(0,(3*Dados!$C$33*Dados!$C$5/8-Dados!$C$33*C16),(7*Dados!$C$33*Dados!$C$5/16-Dados!$C$33*C16),(-Dados!$C$33*Dados!$C$5/16)),-MAX(0,(3*Dados!$C$33*Dados!$C$5/8-Dados!$C$33*C16),(7*Dados!$C$33*Dados!$C$5/16-Dados!$C$33*C16),(-Dados!$C$33*Dados!$C$5/16)))
A17: 9 | B17: =A17*0.5 | C17: =IF(B17<=Dados!$C$5,B17,2*Dados!$C$5-B17) | D17: =(3*Dados!$C$30*Dados!$C$5*C17/8-Dados!$C$30*C17^2/2) | E17: =(3*Dados!$C$32*Dados!$C$5*C17/8-Dados!$C$32*C17^2/2) | F17: =MAX(0,(3*Dados!$C$33*Dados!$C$5*C17/8-Dados!$C$33*C17^2/2),(7*Dados!$C$33*Dados!$C$5*C17/16-Dados!$C$33*C17^2/2),(-Dados!$C$33*Dados!$C$5*C17/16)) | G17: =MIN(0,(3*Dados!$C$33*Dados!$C$5*C17/8-Dados!$C$33*C17^2/2),(7*Dados!$C$33*Dados!$C$5*C17/16-Dados!$C$33*C17^2/2),(-Dados!$C$33*Dados!$C$5*C17/16)) | H17: =E17+Dados!$C$34*F17 | I17: =E17+Dados!$C$34*G17 | J17: =E17+F17 | K17: =E17+G17 | L17: =IF(B17<=Dados!$C$5,1,-1)*(3*Dados!$C$32*Dados!$C$5/8-Dados!$C$32*C17) | M17: =IF(B17<=Dados!$C$5,MAX(0,(3*Dados!$C$33*Dados!$C$5/8-Dados!$C$33*C17),(7*Dados!$C$33*Dados!$C$5/16-Dados!$C$33*C17),(-Dados!$C$33*Dados!$C$5/16)),-MIN(0,(3*Dados!$C$33*Dados!$C$5/8-Dados!$C$33*C17),(7*Dados!$C$33*Dados!$C$5/16-Dados!$C$33*C17),(-Dados!$C$33*Dados!$C$5/16))) | N17: =IF(B17<=Dados!$C$5,MIN(0,(3*Dados!$C$33*Dados!$C$5/8-Dados!$C$33*C17),(7*Dados!$C$33*Dados!$C$5/16-Dados!$C$33*C17),(-Dados!$C$33*Dados!$C$5/16)),-MAX(0,(3*Dados!$C$33*Dados!$C$5/8-Dados!$C$33*C17),(7*Dados!$C$33*Dados!$C$5/16-Dados!$C$33*C17),(-Dados!$C$33*Dados!$C$5/16)))
A18: 10 | B18: =A18*0.5 | C18: =IF(B18<=Dados!$C$5,B18,2*Dados!$C$5-B18) | D18: =(3*Dados!$C$30*Dados!$C$5*C18/8-Dados!$C$30*C18^2/2) | E18: =(3*Dados!$C$32*Dados!$C$5*C18/8-Dados!$C$32*C18^2/2) | F18: =MAX(0,(3*Dados!$C$33*Dados!$C$5*C18/8-Dados!$C$33*C18^2/2),(7*Dados!$C$33*Dados!$C$5*C18/16-Dados!$C$33*C18^2/2),(-Dados!$C$33*Dados!$C$5*C18/16)) | G18: =MIN(0,(3*Dados!$C$33*Dados!$C$5*C18/8-Dados!$C$33*C18^2/2),(7*Dados!$C$33*Dados!$C$5*C18/16-Dados!$C$33*C18^2/2),(-Dados!$C$33*Dados!$C$5*C18/16)) | H18: =E18+Dados!$C$34*F18 | I18: =E18+Dados!$C$34*G18 | J18: =E18+F18 | K18: =E18+G18 | L18: =IF(B18<=Dados!$C$5,1,-1)*(3*Dados!$C$32*Dados!$C$5/8-Dados!$C$32*C18) | M18: =IF(B18<=Dados!$C$5,MAX(0,(3*Dados!$C$33*Dados!$C$5/8-Dados!$C$33*C18),(7*Dados!$C$33*Dados!$C$5/16-Dados!$C$33*C18),(-Dados!$C$33*Dados!$C$5/16)),-MIN(0,(3*Dados!$C$33*Dados!$C$5/8-Dados!$C$33*C18),(7*Dados!$C$33*Dados!$C$5/16-Dados!$C$33*C18),(-Dados!$C$33*Dados!$C$5/16))) | N18: =IF(B18<=Dados!$C$5,MIN(0,(3*Dados!$C$33*Dados!$C$5/8-Dados!$C$33*C18),(7*Dados!$C$33*Dados!$C$5/16-Dados!$C$33*C18),(-Dados!$C$33*Dados!$C$5/16)),-MAX(0,(3*Dados!$C$33*Dados!$C$5/8-Dados!$C$33*C18),(7*Dados!$C$33*Dados!$C$5/16-Dados!$C$33*C18),(-Dados!$C$33*Dados!$C$5/16)))
A19: 11 | B19: =A19*0.5 | C19: =IF(B19<=Dados!$C$5,B19,2*Dados!$C$5-B19) | D19: =(3*Dados!$C$30*Dados!$C$5*C19/8-Dados!$C$30*C19^2/2) | E19: =(3*Dados!$C$32*Dados!$C$5*C19/8-Dados!$C$32*C19^2/2) | F19: =MAX(0,(3*Dados!$C$33*Dados!$C$5*C19/8-Dados!$C$33*C19^2/2),(7*Dados!$C$33*Dados!$C$5*C19/16-Dados!$C$33*C19^2/2),(-Dados!$C$33*Dados!$C$5*C19/16)) | G19: =MIN(0,(3*Dados!$C$33*Dados!$C$5*C19/8-Dados!$C$33*C19^2/2),(7*Dados!$C$33*Dados!$C$5*C19/16-Dados!$C$33*C19^2/2),(-Dados!$C$33*Dados!$C$5*C19/16)) | H19: =E19+Dados!$C$34*F19 | I19: =E19+Dados!$C$34*G19 | J19: =E19+F19 | K19: =E19+G19 | L19: =IF(B19<=Dados!$C$5,1,-1)*(3*Dados!$C$32*Dados!$C$5/8-Dados!$C$32*C19) | M19: =IF(B19<=Dados!$C$5,MAX(0,(3*Dados!$C$33*Dados!$C$5/8-Dados!$C$33*C19),(7*Dados!$C$33*Dados!$C$5/16-Dados!$C$33*C19),(-Dados!$C$33*Dados!$C$5/16)),-MIN(0,(3*Dados!$C$33*Dados!$C$5/8-Dados!$C$33*C19),(7*Dados!$C$33*Dados!$C$5/16-Dados!$C$33*C19),(-Dados!$C$33*Dados!$C$5/16))) | N19: =IF(B19<=Dados!$C$5,MIN(0,(3*Dados!$C$33*Dados!$C$5/8-Dados!$C$33*C19),(7*Dados!$C$33*Dados!$C$5/16-Dados!$C$33*C19),(-Dados!$C$33*Dados!$C$5/16)),-MAX(0,(3*Dados!$C$33*Dados!$C$5/8-Dados!$C$33*C19),(7*Dados!$C$33*Dados!$C$5/16-Dados!$C$33*C19),(-Dados!$C$33*Dados!$C$5/16)))
... A48: 40 | B48: =A48*0.5 | C48: =IF(B48<=Dados!$C$5,B48,2*Dados!$C$5-B48) | D48: =(3*Dados!$C$30*Dados!$C$5*C48/8-Dados!$C$30*C48^2/2) | E48: =(3*Dados!$C$32*Dados!$C$5*C48/8-Dados!$C$32*C48^2/2) | F48: =MAX(0,(3*Dados!$C$33*Dados!$C$5*C48/8-Dados!$C$33*C48^2/2),(7*Dados!$C$33*Dados!$C$5*C48/16-Dados!$C$33*C48^2/2),(-Dados!$C$33*Dados!$C$5*C48/16)) | G48: =MIN(0,(3*Dados!$C$33*Dados!$C$5*C48/8-Dados!$C$33*C48^2/2),(7*Dados!$C$33*Dados!$C$5*C48/16-Dados!$C$33*C48^2/2),(-Dados!$C$33*Dados!$C$5*C48/16)) | H48: =E48+Dados!$C$34*F48 | I48: =E48+Dados!$C$34*G48 | J48: =E48+F48 | K48: =E48+G48 | L48: =IF(B48<=Dados!$C$5,1,-1)*(3*Dados!$C$32*Dados!$C$5/8-Dados!$C$32*C48) | M48: =IF(B48<=Dados!$C$5,MAX(0,(3*Dados!$C$33*Dados!$C$5/8-Dados!$C$33*C48),(7*Dados!$C$33*Dados!$C$5/16-Dados!$C$33*C48),(-Dados!$C$33*Dados!$C$5/16)),-MIN(0,(3*Dados!$C$33*Dados!$C$5/8-Dados!$C$33*C48),(7*Dados!$C$33*Dados!$C$5/16-Dados!$C$33*C48),(-Dados!$C$33*Dados!$C$5/16))) | N48: =IF(B48<=Dados!$C$5,MIN(0,(3*Dados!$C$33*Dados!$C$5/8-Dados!$C$33*C48),(7*Dados!$C$33*Dados!$C$5/16-Dados!$C$33*C48),(-Dados!$C$33*Dados!$C$5/16)),-MAX(0,(3*Dados!$C$33*Dados!$C$5/8-Dados!$C$33*C48),(7*Dados!$C$33*Dados!$C$5/16-Dados!$C$33*C48),(-Dados!$C$33*Dados!$C$5/16)))

Sheet Tracado_Perdas
A1: Traçado do cabo resultante e perdas de protensão (mecanismos físicos)
A2: Cabo resultante parabólico composto (vão + parábola reversa no apoio). Protensão simultânea pelas duas extremidades; atrito (NBR 6118 9.6.3.3.2), cravação, encurtamento elástico e perdas progressivas (NBR 6118 9.6.3.4.2).
A6: i | B6: x | C6: s | D6: e(x) (+ abaixo do CG) | E6: de/dx | F6: α | G6: cos α | H6: sen α | I6: Δα | J6: Σα | K6: Δs (arco) | L6: Σs | M6: σp atrito (da extremidade esq.) | N6: ∫σ dx | O6: Δ(x) = 2[∫σ - σ·x]/Ep | P6: σp após cravação | Q6: Δσ enc. elástico | R6: σp,i (ato) | S6: Pi (ato) | T6: σcp0 (concreto no cabo) | U6: σp,i/fptk | V6: ψ1000 | W6: ψ(t∞)=2,5ψ1000 | X6: χ = -ln(1-ψ) | Y6: η = 1+e²Ac/Ic | Z6: Δσp progressivas | AA6: σp,∞ | AB6: P∞ | AC6: Pi/Pj | AD6: P∞/Pi
B7: m | C7: m | D7: m | F7: rad | I7: rad | J7: rad | K7: m | L7: m | M7: MPa | N7: MPa·m | O7: m | P7: MPa | Q7: MPa | R7: MPa | S7: kN | T7: MPa | Z7: MPa | AA7: MPa | AB7: kN
A8: 0 | B8: =A8*0.5 | C8: =IF(B8<=Dados!$C$5,B8,2*Dados!$C$5-B8) | D8: =IF(C8<=Dados!$C$47,Dados!$C$44-Dados!$C$53*(C8-Dados!$C$52)^2,-Dados!$C$45+Dados!$C$54*(Dados!$C$5-C8)^2) | E8: =IF(B8<=Dados!$C$5,1,-1)*IF(C8<=Dados!$C$47,-2*Dados!$C$53*(C8-Dados!$C$52),-2*Dados!$C$54*(Dados!$C$5-C8)) | F8: =ATAN(E8) | G8: =COS(F8) | H8: =SIN(F8) | I8: 0 | J8: =I8 | K8: 0 | L8: =K8 | M8: =Dados!$C$67*EXP(-Dados!$C$70*J8-Dados!$C$71*L8) | N8: 0 | O8: =2*(N8-M8*B8)/Dados!$C$65 | P8: =IF(B8<=Dados!$C$81,2*Dados!$C$82-M8,M8) | Q8: =MAX(Dados!$C$77*(Dados!$C$59*(1/Dados!$C$8+D8^2/Dados!$C$9)*P8-Esforcos!D8*D8/Dados!$C$9/1000)/(1+Dados!$C$77*Dados!$C$59*(1/Dados!$C$8+D8^2/Dados!$C$9)),0) | R8: =P8-Q8 | S8: =Dados!$C$59*R8*1000 | T8: =(-S8/Dados!$C$8-S8*D8^2/Dados!$C$9+Esforcos!D8*D8/Dados!$C$9)/1000 | U8: =R8/Dados!$C$60 | V8: =IF(U8<=0.5,0,IF(U8<=0.6,(U8-0.5)/0.1*1.3,IF(U8<=0.7,1.3+(U8-0.6)/0.1*1.2,IF(U8<=0.8,2.5+(U8-0.7)/0.1*1,3.5))))/100 | W8: =2.5*V8 | X8: =-LN(1-W8) | Y8: =1+D8^2*Dados!$C$8/Dados!$C$9 | Z8: =(ABS(Dados!$C$74)*Dados!$C$65+Dados!$C$76*ABS(T8)*Dados!$C$73+R8*X8)/((1+X8)+(1+0.5*Dados!$C$73)*Dados!$C$76*Y8*Dados!$C$78) | AA8: =R8-Z8 | AB8: =Dados!$C$59*AA8*1000 | AC8: =S8/Dados!$C$68 | AD8: =AB8/S8
A9: 1 | B9: =A9*0.5 | C9: =IF(B9<=Dados!$C$5,B9,2*Dados!$C$5-B9) | D9: =IF(C9<=Dados!$C$47,Dados!$C$44-Dados!$C$53*(C9-Dados!$C$52)^2,-Dados!$C$45+Dados!$C$54*(Dados!$C$5-C9)^2) | E9: =IF(B9<=Dados!$C$5,1,-1)*IF(C9<=Dados!$C$47,-2*Dados!$C$53*(C9-Dados!$C$52),-2*Dados!$C$54*(Dados!$C$5-C9)) | F9: =ATAN(E9) | G9: =COS(F9) | H9: =SIN(F9) | I9: =ABS(F9-F8) | J9: =J8+I9 | K9: =SQRT((B9-B8)^2+(D9-D8)^2) | L9: =L8+K9 | M9: =Dados!$C$67*EXP(-Dados!$C$70*J9-Dados!$C$71*L9) | N9: =N8+0.5*(M9+M8)*(B9-B8) | O9: =2*(N9-M9*B9)/Dados!$C$65 | P9: =IF(B9<=Dados!$C$81,2*Dados!$C$82-M9,M9) | Q9: =MAX(Dados!$C$77*(Dados!$C$59*(1/Dados!$C$8+D9^2/Dados!$C$9)*P9-Esforcos!D9*D9/Dados!$C$9/1000)/(1+Dados!$C$77*Dados!$C$59*(1/Dados!$C$8+D9^2/Dados!$C$9)),0) | R9: =P9-Q9 | S9: =Dados!$C$59*R9*1000 | T9: =(-S9/Dados!$C$8-S9*D9^2/Dados!$C$9+Esforcos!D9*D9/Dados!$C$9)/1000 | U9: =R9/Dados!$C$60 | V9: =IF(U9<=0.5,0,IF(U9<=0.6,(U9-0.5)/0.1*1.3,IF(U9<=0.7,1.3+(U9-0.6)/0.1*1.2,IF(U9<=0.8,2.5+(U9-0.7)/0.1*1,3.5))))/100 | W9: =2.5*V9 | X9: =-LN(1-W9) | Y9: =1+D9^2*Dados!$C$8/Dados!$C$9 | Z9: =(ABS(Dados!$C$74)*Dados!$C$65+Dados!$C$76*ABS(T9)*Dados!$C$73+R9*X9)/((1+X9)+(1+0.5*Dados!$C$73)*Dados!$C$76*Y9*Dados!$C$78) | AA9: =R9-Z9 | AB9: =Dados!$C$59*AA9*1000 | AC9: =S9/Dados!$C$68 | AD9: =AB9/S9
A10: 2 | B10: =A10*0.5 | C10: =IF(B10<=Dados!$C$5,B10,2*Dados!$C$5-B10) | D10: =IF(C10<=Dados!$C$47,Dados!$C$44-Dados!$C$53*(C10-Dados!$C$52)^2,-Dados!$C$45+Dados!$C$54*(Dados!$C$5-C10)^2) | E10: =IF(B10<=Dados!$C$5,1,-1)*IF(C10<=Dados!$C$47,-2*Dados!$C$53*(C10-Dados!$C$52),-2*Dados!$C$54*(Dados!$C$5-C10)) | F10: =ATAN(E10) | G10: =COS(F10) | H10: =SIN(F10) | I10: =ABS(F10-F9) | J10: =J9+I10 | K10: =SQRT((B10-B9)^2+(D10-D9)^2) | L10: =L9+K10 | M10: =Dados!$C$67*EXP(-Dados!$C$70*J10-Dados!$C$71*L10) | N10: =N9+0.5*(M10+M9)*(B10-B9) | O10: =2*(N10-M10*B10)/Dados!$C$65 | P10: =IF(B10<=Dados!$C$81,2*Dados!$C$82-M10,M10) | Q10: =MAX(Dados!$C$77*(Dados!$C$59*(1/Dados!$C$8+D10^2/Dados!$C$9)*P10-Esforcos!D10*D10/Dados!$C$9/1000)/(1+Dados!$C$77*Dados!$C$59*(1/Dados!$C$8+D10^2/Dados!$C$9)),0) | R10: =P10-Q10 | S10: =Dados!$C$59*R10*1000 | T10: =(-S10/Dados!$C$8-S10*D10^2/Dados!$C$9+Esforcos!D10*D10/Dados!$C$9)/1000 | U10: =R10/Dados!$C$60 | V10: =IF(U10<=0.5,0,IF(U10<=0.6,(U10-0.5)/0.1*1.3,IF(U10<=0.7,1.3+(U10-0.6)/0.1*1.2,IF(U10<=0.8,2.5+(U10-0.7)/0.1*1,3.5))))/100 | W10: =2.5*V10 | X10: =-LN(1-W10) | Y10: =1+D10^2*Dados!$C$8/Dados!$C$9 | Z10: =(ABS(Dados!$C$74)*Dados!$C$65+Dados!$C$76*ABS(T10)*Dados!$C$73+R10*X10)/((1+X10)+(1+0.5*Dados!$C$73)*Dados!$C$76*Y10*Dados!$C$78) | AA10: =R10-Z10 | AB10: =Dados!$C$59*AA10*1000 | AC10: =S10/Dados!$C$68 | AD10: =AB10/S10
A11: 3 | B11: =A11*0.5 | C11: =IF(B11<=Dados!$C$5,B11,2*Dados!$C$5-B11) | D11: =IF(C11<=Dados!$C$47,Dados!$C$44-Dados!$C$53*(C11-Dados!$C$52)^2,-Dados!$C$45+Dados!$C$54*(Dados!$C$5-C11)^2) | E11: =IF(B11<=Dados!$C$5,1,-1)*IF(C11<=Dados!$C$47,-2*Dados!$C$53*(C11-Dados!$C$52),-2*Dados!$C$54*(Dados!$C$5-C11)) | F11: =ATAN(E11) | G11: =COS(F11) | H11: =SIN(F11) | I11: =ABS(F11-F10) | J11: =J10+I11 | K11: =SQRT((B11-B10)^2+(D11-D10)^2) | L11: =L10+K11 | M11: =Dados!$C$67*EXP(-Dados!$C$70*J11-Dados!$C$71*L11) | N11: =N10+0.5*(M11+M10)*(B11-B10) | O11: =2*(N11-M11*B11)/Dados!$C$65 | P11: =IF(B11<=Dados!$C$81,2*Dados!$C$82-M11,M11) | Q11: =MAX(Dados!$C$77*(Dados!$C$59*(1/Dados!$C$8+D11^2/Dados!$C$9)*P11-Esforcos!D11*D11/Dados!$C$9/1000)/(1+Dados!$C$77*Dados!$C$59*(1/Dados!$C$8+D11^2/Dados!$C$9)),0) | R11: =P11-Q11 | S11: =Dados!$C$59*R11*1000 | T11: =(-S11/Dados!$C$8-S11*D11^2/Dados!$C$9+Esforcos!D11*D11/Dados!$C$9)/1000 | U11: =R11/Dados!$C$60 | V11: =IF(U11<=0.5,0,IF(U11<=0.6,(U11-0.5)/0.1*1.3,IF(U11<=0.7,1.3+(U11-0.6)/0.1*1.2,IF(U11<=0.8,2.5+(U11-0.7)/0.1*1,3.5))))/100 | W11: =2.5*V11 | X11: =-LN(1-W11) | Y11: =1+D11^2*Dados!$C$8/Dados!$C$9 | Z11: =(ABS(Dados!$C$74)*Dados!$C$65+Dados!$C$76*ABS(T11)*Dados!$C$73+R11*X11)/((1+X11)+(1+0.5*Dados!$C$73)*Dados!$C$76*Y11*Dados!$C$78) | AA11: =R11-Z11 | AB11: =Dados!$C$59*AA11*1000 | AC11: =S11/Dados!$C$68 | AD11: =AB11/S11
A12: 4 | B12: =A12*0.5 | C12: =IF(B12<=Dados!$C$5,B12,2*Dados!$C$5-B12) | D12: =IF(C12<=Dados!$C$47,Dados!$C$44-Dados!$C$53*(C12-Dados!$C$52)^2,-Dados!$C$45+Dados!$C$54*(Dados!$C$5-C12)^2) | E12: =IF(B12<=Dados!$C$5,1,-1)*IF(C12<=Dados!$C$47,-2*Dados!$C$53*(C12-Dados!$C$52),-2*Dados!$C$54*(Dados!$C$5-C12)) | F12: =ATAN(E12) | G12: =COS(F12) | H12: =SIN(F12) | I12: =ABS(F12-F11) | J12: =J11+I12 | K12: =SQRT((B12-B11)^2+(D12-D11)^2) | L12: =L11+K12 | M12: =Dados!$C$67*EXP(-Dados!$C$70*J12-Dados!$C$71*L12) | N12: =N11+0.5*(M12+M11)*(B12-B11) | O12: =2*(N12-M12*B12)/Dados!$C$65 | P12: =IF(B12<=Dados!$C$81,2*Dados!$C$82-M12,M12) | Q12: =MAX(Dados!$C$77*(Dados!$C$59*(1/Dados!$C$8+D12^2/Dados!$C$9)*P12-Esforcos!D12*D12/Dados!$C$9/1000)/(1+Dados!$C$77*Dados!$C$59*(1/Dados!$C$8+D12^2/Dados!$C$9)),0) | R12: =P12-Q12 | S12: =Dados!$C$59*R12*1000 | T12: =(-S12/Dados!$C$8-S12*D12^2/Dados!$C$9+Esforcos!D12*D12/Dados!$C$9)/1000 | U12: =R12/Dados!$C$60 | V12: =IF(U12<=0.5,0,IF(U12<=0.6,(U12-0.5)/0.1*1.3,IF(U12<=0.7,1.3+(U12-0.6)/0.1*1.2,IF(U12<=0.8,2.5+(U12-0.7)/0.1*1,3.5))))/100 | W12: =2.5*V12 | X12: =-LN(1-W12) | Y12: =1+D12^2*Dados!$C$8/Dados!$C$9 | Z12: =(ABS(Dados!$C$74)*Dados!$C$65+Dados!$C$76*ABS(T12)*Dados!$C$73+R12*X12)/((1+X12)+(1+0.5*Dados!$C$73)*Dados!$C$76*Y12*Dados!$C$78) | AA12: =R12-Z12 | AB12: =Dados!$C$59*AA12*1000 | AC12: =S12/Dados!$C$68 | AD12: =AB12/S12
A13: 5 | B13: =A13*0.5 | C13: =IF(B13<=Dados!$C$5,B13,2*Dados!$C$5-B13) | D13: =IF(C13<=Dados!$C$47,Dados!$C$44-Dados!$C$53*(C13-Dados!$C$52)^2,-Dados!$C$45+Dados!$C$54*(Dados!$C$5-C13)^2) | E13: =IF(B13<=Dados!$C$5,1,-1)*IF(C13<=Dados!$C$47,-2*Dados!$C$53*(C13-Dados!$C$52),-2*Dados!$C$54*(Dados!$C$5-C13)) | F13: =ATAN(E13) | G13: =COS(F13) | H13: =SIN(F13) | I13: =ABS(F13-F12) | J13: =J12+I13 | K13: =SQRT((B13-B12)^2+(D13-D12)^2) | L13: =L12+K13 | M13: =Dados!$C$67*EXP(-Dados!$C$70*J13-Dados!$C$71*L13) | N13: =N12+0.5*(M13+M12)*(B13-B12) | O13: =2*(N13-M13*B13)/Dados!$C$65 | P13: =IF(B13<=Dados!$C$81,2*Dados!$C$82-M13,M13) | Q13: =MAX(Dados!$C$77*(Dados!$C$59*(1/Dados!$C$8+D13^2/Dados!$C$9)*P13-Esforcos!D13*D13/Dados!$C$9/1000)/(1+Dados!$C$77*Dados!$C$59*(1/Dados!$C$8+D13^2/Dados!$C$9)),0) | R13: =P13-Q13 | S13: =Dados!$C$59*R13*1000 | T13: =(-S13/Dados!$C$8-S13*D13^2/Dados!$C$9+Esforcos!D13*D13/Dados!$C$9)/1000 | U13: =R13/Dados!$C$60 | V13: =IF(U13<=0.5,0,IF(U13<=0.6,(U13-0.5)/0.1*1.3,IF(U13<=0.7,1.3+(U13-0.6)/0.1*1.2,IF(U13<=0.8,2.5+(U13-0.7)/0.1*1,3.5))))/100 | W13: =2.5*V13 | X13: =-LN(1-W13) | Y13: =1+D13^2*Dados!$C$8/Dados!$C$9 | Z13: =(ABS(Dados!$C$74)*Dados!$C$65+Dados!$C$76*ABS(T13)*Dados!$C$73+R13*X13)/((1+X13)+(1+0.5*Dados!$C$73)*Dados!$C$76*Y13*Dados!$C$78) | AA13: =R13-Z13 | AB13: =Dados!$C$59*AA13*1000 | AC13: =S13/Dados!$C$68 | AD13: =AB13/S13
A14: 6 | B14: =A14*0.5 | C14: =IF(B14<=Dados!$C$5,B14,2*Dados!$C$5-B14) | D14: =IF(C14<=Dados!$C$47,Dados!$C$44-Dados!$C$53*(C14-Dados!$C$52)^2,-Dados!$C$45+Dados!$C$54*(Dados!$C$5-C14)^2) | E14: =IF(B14<=Dados!$C$5,1,-1)*IF(C14<=Dados!$C$47,-2*Dados!$C$53*(C14-Dados!$C$52),-2*Dados!$C$54*(Dados!$C$5-C14)) | F14: =ATAN(E14) | G14: =COS(F14) | H14: =SIN(F14) | I14: =ABS(F14-F13) | J14: =J13+I14 | K14: =SQRT((B14-B13)^2+(D14-D13)^2) | L14: =L13+K14 | M14: =Dados!$C$67*EXP(-Dados!$C$70*J14-Dados!$C$71*L14) | N14: =N13+0.5*(M14+M13)*(B14-B13) | O14: =2*(N14-M14*B14)/Dados!$C$65 | P14: =IF(B14<=Dados!$C$81,2*Dados!$C$82-M14,M14) | Q14: =MAX(Dados!$C$77*(Dados!$C$59*(1/Dados!$C$8+D14^2/Dados!$C$9)*P14-Esforcos!D14*D14/Dados!$C$9/1000)/(1+Dados!$C$77*Dados!$C$59*(1/Dados!$C$8+D14^2/Dados!$C$9)),0) | R14: =P14-Q14 | S14: =Dados!$C$59*R14*1000 | T14: =(-S14/Dados!$C$8-S14*D14^2/Dados!$C$9+Esforcos!D14*D14/Dados!$C$9)/1000 | U14: =R14/Dados!$C$60 | V14: =IF(U14<=0.5,0,IF(U14<=0.6,(U14-0.5)/0.1*1.3,IF(U14<=0.7,1.3+(U14-0.6)/0.1*1.2,IF(U14<=0.8,2.5+(U14-0.7)/0.1*1,3.5))))/100 | W14: =2.5*V14 | X14: =-LN(1-W14) | Y14: =1+D14^2*Dados!$C$8/Dados!$C$9 | Z14: =(ABS(Dados!$C$74)*Dados!$C$65+Dados!$C$76*ABS(T14)*Dados!$C$73+R14*X14)/((1+X14)+(1+0.5*Dados!$C$73)*Dados!$C$76*Y14*Dados!$C$78) | AA14: =R14-Z14 | AB14: =Dados!$C$59*AA14*1000 | AC14: =S14/Dados!$C$68 | AD14: =AB14/S14
A15: 7 | B15: =A15*0.5 | C15: =IF(B15<=Dados!$C$5,B15,2*Dados!$C$5-B15) | D15: =IF(C15<=Dados!$C$47,Dados!$C$44-Dados!$C$53*(C15-Dados!$C$52)^2,-Dados!$C$45+Dados!$C$54*(Dados!$C$5-C15)^2) | E15: =IF(B15<=Dados!$C$5,1,-1)*IF(C15<=Dados!$C$47,-2*Dados!$C$53*(C15-Dados!$C$52),-2*Dados!$C$54*(Dados!$C$5-C15)) | F15: =ATAN(E15) | G15: =COS(F15) | H15: =SIN(F15) | I15: =ABS(F15-F14) | J15: =J14+I15 | K15: =SQRT((B15-B14)^2+(D15-D14)^2) | L15: =L14+K15 | M15: =Dados!$C$67*EXP(-Dados!$C$70*J15-Dados!$C$71*L15) | N15: =N14+0.5*(M15+M14)*(B15-B14) | O15: =2*(N15-M15*B15)/Dados!$C$65 | P15: =IF(B15<=Dados!$C$81,2*Dados!$C$82-M15,M15) | Q15: =MAX(Dados!$C$77*(Dados!$C$59*(1/Dados!$C$8+D15^2/Dados!$C$9)*P15-Esforcos!D15*D15/Dados!$C$9/1000)/(1+Dados!$C$77*Dados!$C$59*(1/Dados!$C$8+D15^2/Dados!$C$9)),0) | R15: =P15-Q15 | S15: =Dados!$C$59*R15*1000 | T15: =(-S15/Dados!$C$8-S15*D15^2/Dados!$C$9+Esforcos!D15*D15/Dados!$C$9)/1000 | U15: =R15/Dados!$C$60 | V15: =IF(U15<=0.5,0,IF(U15<=0.6,(U15-0.5)/0.1*1.3,IF(U15<=0.7,1.3+(U15-0.6)/0.1*1.2,IF(U15<=0.8,2.5+(U15-0.7)/0.1*1,3.5))))/100 | W15: =2.5*V15 | X15: =-LN(1-W15) | Y15: =1+D15^2*Dados!$C$8/Dados!$C$9 | Z15: =(ABS(Dados!$C$74)*Dados!$C$65+Dados!$C$76*ABS(T15)*Dados!$C$73+R15*X15)/((1+X15)+(1+0.5*Dados!$C$73)*Dados!$C$76*Y15*Dados!$C$78) | AA15: =R15-Z15 | AB15: =Dados!$C$59*AA15*1000 | AC15: =S15/Dados!$C$68 | AD15: =AB15/S15
A16: 8 | B16: =A16*0.5 | C16: =IF(B16<=Dados!$C$5,B16,2*Dados!$C$5-B16) | D16: =IF(C16<=Dados!$C$47,Dados!$C$44-Dados!$C$53*(C16-Dados!$C$52)^2,-Dados!$C$45+Dados!$C$54*(Dados!$C$5-C16)^2) | E16: =IF(B16<=Dados!$C$5,1,-1)*IF(C16<=Dados!$C$47,-2*Dados!$C$53*(C16-Dados!$C$52),-2*Dados!$C$54*(Dados!$C$5-C16)) | F16: =ATAN(E16) | G16: =COS(F16) | H16: =SIN(F16) | I16: =ABS(F16-F15) | J16: =J15+I16 | K16: =SQRT((B16-B15)^2+(D16-D15)^2) | L16: =L15+K16 | M16: =Dados!$C$67*EXP(-Dados!$C$70*J16-Dados!$C$71*L16) | N16: =N15+0.5*(M16+M15)*(B16-B15) | O16: =2*(N16-M16*B16)/Dados!$C$65 | P16: =IF(B16<=Dados!$C$81,2*Dados!$C$82-M16,M16) | Q16: =MAX(Dados!$C$77*(Dados!$C$59*(1/Dados!$C$8+D16^2/Dados!$C$9)*P16-Esforcos!D16*D16/Dados!$C$9/1000)/(1+Dados!$C$77*Dados!$C$59*(1/Dados!$C$8+D16^2/Dados!$C$9)),0) | R16: =P16-Q16 | S16: =Dados!$C$59*R16*1000 | T16: =(-S16/Dados!$C$8-S16*D16^2/Dados!$C$9+Esforcos!D16*D16/Dados!$C$9)/1000 | U16: =R16/Dados!$C$60 | V16: =IF(U16<=0.5,0,IF(U16<=0.6,(U16-0.5)/0.1*1.3,IF(U16<=0.7,1.3+(U16-0.6)/0.1*1.2,IF(U16<=0.8,2.5+(U16-0.7)/0.1*1,3.5))))/100 | W16: =2.5*V16 | X16: =-LN(1-W16) | Y16: =1+D16^2*Dados!$C$8/Dados!$C$9 | Z16: =(ABS(Dados!$C$74)*Dados!$C$65+Dados!$C$76*ABS(T16)*Dados!$C$73+R16*X16)/((1+X16)+(1+0.5*Dados!$C$73)*Dados!$C$76*Y16*Dados!$C$78) | AA16: =R16-Z16 | AB16: =Dados!$C$59*AA16*1000 | AC16: =S16/Dados!$C$68 | AD16: =AB16/S16
A17: 9 | B17: =A17*0.5 | C17: =IF(B17<=Dados!$C$5,B17,2*Dados!$C$5-B17) | D17: =IF(C17<=Dados!$C$47,Dados!$C$44-Dados!$C$53*(C17-Dados!$C$52)^2,-Dados!$C$45+Dados!$C$54*(Dados!$C$5-C17)^2) | E17: =IF(B17<=Dados!$C$5,1,-1)*IF(C17<=Dados!$C$47,-2*Dados!$C$53*(C17-Dados!$C$52),-2*Dados!$C$54*(Dados!$C$5-C17)) | F17: =ATAN(E17) | G17: =COS(F17) | H17: =SIN(F17) | I17: =ABS(F17-F16) | J17: =J16+I17 | K17: =SQRT((B17-B16)^2+(D17-D16)^2) | L17: =L16+K17 | M17: =Dados!$C$67*EXP(-Dados!$C$70*J17-Dados!$C$71*L17) | N17: =N16+0.5*(M17+M16)*(B17-B16) | O17: =2*(N17-M17*B17)/Dados!$C$65 | P17: =IF(B17<=Dados!$C$81,2*Dados!$C$82-M17,M17) | Q17: =MAX(Dados!$C$77*(Dados!$C$59*(1/Dados!$C$8+D17^2/Dados!$C$9)*P17-Esforcos!D17*D17/Dados!$C$9/1000)/(1+Dados!$C$77*Dados!$C$59*(1/Dados!$C$8+D17^2/Dados!$C$9)),0) | R17: =P17-Q17 | S17: =Dados!$C$59*R17*1000 | T17: =(-S17/Dados!$C$8-S17*D17^2/Dados!$C$9+Esforcos!D17*D17/Dados!$C$9)/1000 | U17: =R17/Dados!$C$60 | V17: =IF(U17<=0.5,0,IF(U17<=0.6,(U17-0.5)/0.1*1.3,IF(U17<=0.7,1.3+(U17-0.6)/0.1*1.2,IF(U17<=0.8,2.5+(U17-0.7)/0.1*1,3.5))))/100 | W17: =2.5*V17 | X17: =-LN(1-W17) | Y17: =1+D17^2*Dados!$C$8/Dados!$C$9 | Z17: =(ABS(Dados!$C$74)*Dados!$C$65+Dados!$C$76*ABS(T17)*Dados!$C$73+R17*X17)/((1+X17)+(1+0.5*Dados!$C$73)*Dados!$C$76*Y17*Dados!$C$78) | AA17: =R17-Z17 | AB17: =Dados!$C$59*AA17*1000 | AC17: =S17/Dados!$C$68 | AD17: =AB17/S17
A18: 10 | B18: =A18*0.5 | C18: =IF(B18<=Dados!$C$5,B18,2*Dados!$C$5-B18) | D18: =IF(C18<=Dados!$C$47,Dados!$C$44-Dados!$C$53*(C18-Dados!$C$52)^2,-Dados!$C$45+Dados!$C$54*(Dados!$C$5-C18)^2) | E18: =IF(B18<=Dados!$C$5,1,-1)*IF(C18<=Dados!$C$47,-2*Dados!$C$53*(C18-Dados!$C$52),-2*Dados!$C$54*(Dados!$C$5-C18)) | F18: =ATAN(E18) | G18: =COS(F18) | H18: =SIN(F18) | I18: =ABS(F18-F17) | J18: =J17+I18 | K18: =SQRT((B18-B17)^2+(D18-D17)^2) | L18: =L17+K18 | M18: =Dados!$C$67*EXP(-Dados!$C$70*J18-Dados!$C$71*L18) | N18: =N17+0.5*(M18+M17)*(B18-B17) | O18: =2*(N18-M18*B18)/Dados!$C$65 | P18: =IF(B18<=Dados!$C$81,2*Dados!$C$82-M18,M18) | Q18: =MAX(Dados!$C$77*(Dados!$C$59*(1/Dados!$C$8+D18^2/Dados!$C$9)*P18-Esforcos!D18*D18/Dados!$C$9/1000)/(1+Dados!$C$77*Dados!$C$59*(1/Dados!$C$8+D18^2/Dados!$C$9)),0) | R18: =P18-Q18 | S18: =Dados!$C$59*R18*1000 | T18: =(-S18/Dados!$C$8-S18*D18^2/Dados!$C$9+Esforcos!D18*D18/Dados!$C$9)/1000 | U18: =R18/Dados!$C$60 | V18: =IF(U18<=0.5,0,IF(U18<=0.6,(U18-0.5)/0.1*1.3,IF(U18<=0.7,1.3+(U18-0.6)/0.1*1.2,IF(U18<=0.8,2.5+(U18-0.7)/0.1*1,3.5))))/100 | W18: =2.5*V18 | X18: =-LN(1-W18) | Y18: =1+D18^2*Dados!$C$8/Dados!$C$9 | Z18: =(ABS(Dados!$C$74)*Dados!$C$65+Dados!$C$76*ABS(T18)*Dados!$C$73+R18*X18)/((1+X18)+(1+0.5*Dados!$C$73)*Dados!$C$76*Y18*Dados!$C$78) | AA18: =R18-Z18 | AB18: =Dados!$C$59*AA18*1000 | AC18: =S18/Dados!$C$68 | AD18: =AB18/S18
A19: 11 | B19: =A19*0.5 | C19: =IF(B19<=Dados!$C$5,B19,2*Dados!$C$5-B19) | D19: =IF(C19<=Dados!$C$47,Dados!$C$44-Dados!$C$53*(C19-Dados!$C$52)^2,-Dados!$C$45+Dados!$C$54*(Dados!$C$5-C19)^2) | E19: =IF(B19<=Dados!$C$5,1,-1)*IF(C19<=Dados!$C$47,-2*Dados!$C$53*(C19-Dados!$C$52),-2*Dados!$C$54*(Dados!$C$5-C19)) | F19: =ATAN(E19) | G19: =COS(F19) | H19: =SIN(F19) | I19: =ABS(F19-F18) | J19: =J18+I19 | K19: =SQRT((B19-B18)^2+(D19-D18)^2) | L19: =L18+K19 | M19: =Dados!$C$67*EXP(-Dados!$C$70*J19-Dados!$C$71*L19) | N19: =N18+0.5*(M19+M18)*(B19-B18) | O19: =2*(N19-M19*B19)/Dados!$C$65 | P19: =IF(B19<=Dados!$C$81,2*Dados!$C$82-M19,M19) | Q19: =MAX(Dados!$C$77*(Dados!$C$59*(1/Dados!$C$8+D19^2/Dados!$C$9)*P19-Esforcos!D19*D19/Dados!$C$9/1000)/(1+Dados!$C$77*Dados!$C$59*(1/Dados!$C$8+D19^2/Dados!$C$9)),0) | R19: =P19-Q19 | S19: =Dados!$C$59*R19*1000 | T19: =(-S19/Dados!$C$8-S19*D19^2/Dados!$C$9+Esforcos!D19*D19/Dados!$C$9)/1000 | U19: =R19/Dados!$C$60 | V19: =IF(U19<=0.5,0,IF(U19<=0.6,(U19-0.5)/0.1*1.3,IF(U19<=0.7,1.3+(U19-0.6)/0.1*1.2,IF(U19<=0.8,2.5+(U19-0.7)/0.1*1,3.5))))/100 | W19: =2.5*V19 | X19: =-LN(1-W19) | Y19: =1+D19^2*Dados!$C$8/Dados!$C$9 | Z19: =(ABS(Dados!$C$74)*Dados!$C$65+Dados!$C$76*ABS(T19)*Dados!$C$73+R19*X19)/((1+X19)+(1+0.5*Dados!$C$73)*Dados!$C$76*Y19*Dados!$C$78) | AA19: =R19-Z19 | AB19: =Dados!$C$59*AA19*1000 | AC19: =S19/Dados!$C$68 | AD19: =AB19/S19
A20: 12 | B20: =A20*0.5 | C20: =IF(B20<=Dados!$C$5,B20,2*Dados!$C$5-B20) | D20: =IF(C20<=Dados!$C$47,Dados!$C$44-Dados!$C$53*(C20-Dados!$C$52)^2,-Dados!$C$45+Dados!$C$54*(Dados!$C$5-C20)^2) | E20: =IF(B20<=Dados!$C$5,1,-1)*IF(C20<=Dados!$C$47,-2*Dados!$C$53*(C20-Dados!$C$52),-2*Dados!$C$54*(Dados!$C$5-C20)) | F20: =ATAN(E20) | G20: =COS(F20) | H20: =SIN(F20) | I20: =ABS(F20-F19) | J20: =J19+I20 | K20: =SQRT((B20-B19)^2+(D20-D19)^2) | L20: =L19+K20 | M20: =Dados!$C$67*EXP(-Dados!$C$70*J20-Dados!$C$71*L20) | N20: =N19+0.5*(M20+M19)*(B20-B19) | O20: =2*(N20-M20*B20)/Dados!$C$65 | P20: =IF(B20<=Dados!$C$81,2*Dados!$C$82-M20,M20) | Q20: =MAX(Dados!$C$77*(Dados!$C$59*(1/Dados!$C$8+D20^2/Dados!$C$9)*P20-Esforcos!D20*D20/Dados!$C$9/1000)/(1+Dados!$C$77*Dados!$C$59*(1/Dados!$C$8+D20^2/Dados!$C$9)),0) | R20: =P20-Q20 | S20: =Dados!$C$59*R20*1000 | T20: =(-S20/Dados!$C$8-S20*D20^2/Dados!$C$9+Esforcos!D20*D20/Dados!$C$9)/1000 | U20: =R20/Dados!$C$60 | V20: =IF(U20<=0.5,0,IF(U20<=0.6,(U20-0.5)/0.1*1.3,IF(U20<=0.7,1.3+(U20-0.6)/0.1*1.2,IF(U20<=0.8,2.5+(U20-0.7)/0.1*1,3.5))))/100 | W20: =2.5*V20 | X20: =-LN(1-W20) | Y20: =1+D20^2*Dados!$C$8/Dados!$C$9 | Z20: =(ABS(Dados!$C$74)*Dados!$C$65+Dados!$C$76*ABS(T20)*Dados!$C$73+R20*X20)/((1+X20)+(1+0.5*Dados!$C$73)*Dados!$C$76*Y20*Dados!$C$78) | AA20: =R20-Z20 | AB20: =Dados!$C$59*AA20*1000 | AC20: =S20/Dados!$C$68 | AD20: =AB20/S20
... A28: 20 | B28: =A28*0.5 | C28: =IF(B28<=Dados!$C$5,B28,2*Dados!$C$5-B28) | D28: =IF(C28<=Dados!$C$47,Dados!$C$44-Dados!$C$53*(C28-Dados!$C$52)^2,-Dados!$C$45+Dados!$C$54*(Dados!$C$5-C28)^2) | E28: =IF(B28<=Dados!$C$5,1,-1)*IF(C28<=Dados!$C$47,-2*Dados!$C$53*(C28-Dados!$C$52),-2*Dados!$C$54*(Dados!$C$5-C28)) | F28: =ATAN(E28) | G28: =COS(F28) | H28: =SIN(F28) | I28: =ABS(F28-F27) | J28: =J27+I28 | K28: =SQRT((B28-B27)^2+(D28-D27)^2) | L28: =L27+K28 | M28: =Dados!$C$67*EXP(-Dados!$C$70*J28-Dados!$C$71*L28) | N28: =N27+0.5*(M28+M27)*(B28-B27) | O28: =2*(N28-M28*B28)/Dados!$C$65 | P28: =IF(B28<=Dados!$C$81,2*Dados!$C$82-M28,M28) | Q28: =MAX(Dados!$C$77*(Dados!$C$59*(1/Dados!$C$8+D28^2/Dados!$C$9)*P28-Esforcos!D28*D28/Dados!$C$9/1000)/(1+Dados!$C$77*Dados!$C$59*(1/Dados!$C$8+D28^2/Dados!$C$9)),0) | R28: =P28-Q28 | S28: =Dados!$C$59*R28*1000 | T28: =(-S28/Dados!$C$8-S28*D28^2/Dados!$C$9+Esforcos!D28*D28/Dados!$C$9)/1000 | U28: =R28/Dados!$C$60 | V28: =IF(U28<=0.5,0,IF(U28<=0.6,(U28-0.5)/0.1*1.3,IF(U28<=0.7,1.3+(U28-0.6)/0.1*1.2,IF(U28<=0.8,2.5+(U28-0.7)/0.1*1,3.5))))/100 | W28: =2.5*V28 | X28: =-LN(1-W28) | Y28: =1+D28^2*Dados!$C$8/Dados!$C$9 | Z28: =(ABS(Dados!$C$74)*Dados!$C$65+Dados!$C$76*ABS(T28)*Dados!$C$73+R28*X28)/((1+X28)+(1+0.5*Dados!$C$73)*Dados!$C$76*Y28*Dados!$C$78) | AA28: =R28-Z28 | AB28: =Dados!$C$59*AA28*1000 | AC28: =S28/Dados!$C$68 | AD28: =AB28/S28
A29: 21 | B29: =A29*0.5 | C29: =IF(B29<=Dados!$C$5,B29,2*Dados!$C$5-B29) | D29: =IF(C29<=Dados!$C$47,Dados!$C$44-Dados!$C$53*(C29-Dados!$C$52)^2,-Dados!$C$45+Dados!$C$54*(Dados!$C$5-C29)^2) | E29: =IF(B29<=Dados!$C$5,1,-1)*IF(C29<=Dados!$C$47,-2*Dados!$C$53*(C29-Dados!$C$52),-2*Dados!$C$54*(Dados!$C$5-C29)) | F29: =ATAN(E29) | G29: =COS(F29) | H29: =SIN(F29) | I29: =ABS(F29-F28) | J29: =J28+I29 | K29: =SQRT((B29-B28)^2+(D29-D28)^2) | L29: =L28+K29 | M29: =Dados!$C$67*EXP(-Dados!$C$70*J29-Dados!$C$71*L29) | N29: =N28+0.5*(M29+M28)*(B29-B28) | P29: =P27 | Q29: =MAX(Dados!$C$77*(Dados!$C$59*(1/Dados!$C$8+D29^2/Dados!$C$9)*P29-Esforcos!D29*D29/Dados!$C$9/1000)/(1+Dados!$C$77*Dados!$C$59*(1/Dados!$C$8+D29^2/Dados!$C$9)),0) | R29: =P29-Q29 | S29: =Dados!$C$59*R29*1000 | T29: =(-S29/Dados!$C$8-S29*D29^2/Dados!$C$9+Esforcos!D29*D29/Dados!$C$9)/1000 | U29: =R29/Dados!$C$60 | V29: =IF(U29<=0.5,0,IF(U29<=0.6,(U29-0.5)/0.1*1.3,IF(U29<=0.7,1.3+(U29-0.6)/0.1*1.2,IF(U29<=0.8,2.5+(U29-0.7)/0.1*1,3.5))))/100 | W29: =2.5*V29 | X29: =-LN(1-W29) | Y29: =1+D29^2*Dados!$C$8/Dados!$C$9 | Z29: =(ABS(Dados!$C$74)*Dados!$C$65+Dados!$C$76*ABS(T29)*Dados!$C$73+R29*X29)/((1+X29)+(1+0.5*Dados!$C$73)*Dados!$C$76*Y29*Dados!$C$78) | AA29: =R29-Z29 | AB29: =Dados!$C$59*AA29*1000 | AC29: =S29/Dados!$C$68 | AD29: =AB29/S29
A30: 22 | B30: =A30*0.5 | C30: =IF(B30<=Dados!$C$5,B30,2*Dados!$C$5-B30) | D30: =IF(C30<=Dados!$C$47,Dados!$C$44-Dados!$C$53*(C30-Dados!$C$52)^2,-Dados!$C$45+Dados!$C$54*(Dados!$C$5-C30)^2) | E30: =IF(B30<=Dados!$C$5,1,-1)*IF(C30<=Dados!$C$47,-2*Dados!$C$53*(C30-Dados!$C$52),-2*Dados!$C$54*(Dados!$C$5-C30)) | F30: =ATAN(E30) | G30: =COS(F30) | H30: =SIN(F30) | I30: =ABS(F30-F29) | J30: =J29+I30 | K30: =SQRT((B30-B29)^2+(D30-D29)^2) | L30: =L29+K30 | M30: =Dados!$C$67*EXP(-Dados!$C$70*J30-Dados!$C$71*L30) | N30: =N29+0.5*(M30+M29)*(B30-B29) | P30: =P26 | Q30: =MAX(Dados!$C$77*(Dados!$C$59*(1/Dados!$C$8+D30^2/Dados!$C$9)*P30-Esforcos!D30*D30/Dados!$C$9/1000)/(1+Dados!$C$77*Dados!$C$59*(1/Dados!$C$8+D30^2/Dados!$C$9)),0) | R30: =P30-Q30 | S30: =Dados!$C$59*R30*1000 | T30: =(-S30/Dados!$C$8-S30*D30^2/Dados!$C$9+Esforcos!D30*D30/Dados!$C$9)/1000 | U30: =R30/Dados!$C$60 | V30: =IF(U30<=0.5,0,IF(U30<=0.6,(U30-0.5)/0.1*1.3,IF(U30<=0.7,1.3+(U30-0.6)/0.1*1.2,IF(U30<=0.8,2.5+(U30-0.7)/0.1*1,3.5))))/100 | W30: =2.5*V30 | X30: =-LN(1-W30) | Y30: =1+D30^2*Dados!$C$8/Dados!$C$9 | Z30: =(ABS(Dados!$C$74)*Dados!$C$65+Dados!$C$76*ABS(T30)*Dados!$C$73+R30*X30)/((1+X30)+(1+0.5*Dados!$C$73)*Dados!$C$76*Y30*Dados!$C$78) | AA30: =R30-Z30 | AB30: =Dados!$C$59*AA30*1000 | AC30: =S30/Dados!$C$68 | AD30: =AB30/S30
A31: 23 | B31: =A31*0.5 | C31: =IF(B31<=Dados!$C$5,B31,2*Dados!$C$5-B31) | D31: =IF(C31<=Dados!$C$47,Dados!$C$44-Dados!$C$53*(C31-Dados!$C$52)^2,-Dados!$C$45+Dados!$C$54*(Dados!$C$5-C31)^2) | E31: =IF(B31<=Dados!$C$5,1,-1)*IF(C31<=Dados!$C$47,-2*Dados!$C$53*(C31-Dados!$C$52),-2*Dados!$C$54*(Dados!$C$5-C31)) | F31: =ATAN(E31) | G31: =COS(F31) | H31: =SIN(F31) | I31: =ABS(F31-F30) | J31: =J30+I31 | K31: =SQRT((B31-B30)^2+(D31-D30)^2) | L31: =L30+K31 | M31: =Dados!$C$67*EXP(-Dados!$C$70*J31-Dados!$C$71*L31) | N31: =N30+0.5*(M31+M30)*(B31-B30) | P31: =P25 | Q31: =MAX(Dados!$C$77*(Dados!$C$59*(1/Dados!$C$8+D31^2/Dados!$C$9)*P31-Esforcos!D31*D31/Dados!$C$9/1000)/(1+Dados!$C$77*Dados!$C$59*(1/Dados!$C$8+D31^2/Dados!$C$9)),0) | R31: =P31-Q31 | S31: =Dados!$C$59*R31*1000 | T31: =(-S31/Dados!$C$8-S31*D31^2/Dados!$C$9+Esforcos!D31*D31/Dados!$C$9)/1000 | U31: =R31/Dados!$C$60 | V31: =IF(U31<=0.5,0,IF(U31<=0.6,(U31-0.5)/0.1*1.3,IF(U31<=0.7,1.3+(U31-0.6)/0.1*1.2,IF(U31<=0.8,2.5+(U31-0.7)/0.1*1,3.5))))/100 | W31: =2.5*V31 | X31: =-LN(1-W31) | Y31: =1+D31^2*Dados!$C$8/Dados!$C$9 | Z31: =(ABS(Dados!$C$74)*Dados!$C$65+Dados!$C$76*ABS(T31)*Dados!$C$73+R31*X31)/((1+X31)+(1+0.5*Dados!$C$73)*Dados!$C$76*Y31*Dados!$C$78) | AA31: =R31-Z31 | AB31: =Dados!$C$59*AA31*1000 | AC31: =S31/Dados!$C$68 | AD31: =AB31/S31
A32: 24 | B32: =A32*0.5 | C32: =IF(B32<=Dados!$C$5,B32,2*Dados!$C$5-B32) | D32: =IF(C32<=Dados!$C$47,Dados!$C$44-Dados!$C$53*(C32-Dados!$C$52)^2,-Dados!$C$45+Dados!$C$54*(Dados!$C$5-C32)^2) | E32: =IF(B32<=Dados!$C$5,1,-1)*IF(C32<=Dados!$C$47,-2*Dados!$C$53*(C32-Dados!$C$52),-2*Dados!$C$54*(Dados!$C$5-C32)) | F32: =ATAN(E32) | G32: =COS(F32) | H32: =SIN(F32) | I32: =ABS(F32-F31) | J32: =J31+I32 | K32: =SQRT((B32-B31)^2+(D32-D31)^2) | L32: =L31+K32 | M32: =Dados!$C$67*EXP(-Dados!$C$70*J32-Dados!$C$71*L32) | N32: =N31+0.5*(M32+M31)*(B32-B31) | P32: =P24 | Q32: =MAX(Dados!$C$77*(Dados!$C$59*(1/Dados!$C$8+D32^2/Dados!$C$9)*P32-Esforcos!D32*D32/Dados!$C$9/1000)/(1+Dados!$C$77*Dados!$C$59*(1/Dados!$C$8+D32^2/Dados!$C$9)),0) | R32: =P32-Q32 | S32: =Dados!$C$59*R32*1000 | T32: =(-S32/Dados!$C$8-S32*D32^2/Dados!$C$9+Esforcos!D32*D32/Dados!$C$9)/1000 | U32: =R32/Dados!$C$60 | V32: =IF(U32<=0.5,0,IF(U32<=0.6,(U32-0.5)/0.1*1.3,IF(U32<=0.7,1.3+(U32-0.6)/0.1*1.2,IF(U32<=0.8,2.5+(U32-0.7)/0.1*1,3.5))))/100 | W32: =2.5*V32 | X32: =-LN(1-W32) | Y32: =1+D32^2*Dados!$C$8/Dados!$C$9 | Z32: =(ABS(Dados!$C$74)*Dados!$C$65+Dados!$C$76*ABS(T32)*Dados!$C$73+R32*X32)/((1+X32)+(1+0.5*Dados!$C$73)*Dados!$C$76*Y32*Dados!$C$78) | AA32: =R32-Z32 | AB32: =Dados!$C$59*AA32*1000 | AC32: =S32/Dados!$C$68 | AD32: =AB32/S32
A33: 25 | B33: =A33*0.5 | C33: =IF(B33<=Dados!$C$5,B33,2*Dados!$C$5-B33) | D33: =IF(C33<=Dados!$C$47,Dados!$C$44-Dados!$C$53*(C33-Dados!$C$52)^2,-Dados!$C$45+Dados!$C$54*(Dados!$C$5-C33)^2) | E33: =IF(B33<=Dados!$C$5,1,-1)*IF(C33<=Dados!$C$47,-2*Dados!$C$53*(C33-Dados!$C$52),-2*Dados!$C$54*(Dados!$C$5-C33)) | F33: =ATAN(E33) | G33: =COS(F33) | H33: =SIN(F33) | I33: =ABS(F33-F32) | J33: =J32+I33 | K33: =SQRT((B33-B32)^2+(D33-D32)^2) | L33: =L32+K33 | M33: =Dados!$C$67*EXP(-Dados!$C$70*J33-Dados!$C$71*L33) | N33: =N32+0.5*(M33+M32)*(B33-B32) | P33: =P23 | Q33: =MAX(Dados!$C$77*(Dados!$C$59*(1/Dados!$C$8+D33^2/Dados!$C$9)*P33-Esforcos!D33*D33/Dados!$C$9/1000)/(1+Dados!$C$77*Dados!$C$59*(1/Dados!$C$8+D33^2/Dados!$C$9)),0) | R33: =P33-Q33 | S33: =Dados!$C$59*R33*1000 | T33: =(-S33/Dados!$C$8-S33*D33^2/Dados!$C$9+Esforcos!D33*D33/Dados!$C$9)/1000 | U33: =R33/Dados!$C$60 | V33: =IF(U33<=0.5,0,IF(U33<=0.6,(U33-0.5)/0.1*1.3,IF(U33<=0.7,1.3+(U33-0.6)/0.1*1.2,IF(U33<=0.8,2.5+(U33-0.7)/0.1*1,3.5))))/100 | W33: =2.5*V33 | X33: =-LN(1-W33) | Y33: =1+D33^2*Dados!$C$8/Dados!$C$9 | Z33: =(ABS(Dados!$C$74)*Dados!$C$65+Dados!$C$76*ABS(T33)*Dados!$C$73+R33*X33)/((1+X33)+(1+0.5*Dados!$C$73)*Dados!$C$76*Y33*Dados!$C$78) | AA33: =R33-Z33 | AB33: =Dados!$C$59*AA33*1000 | AC33: =S33/Dados!$C$68 | AD33: =AB33/S33
A34: 26 | B34: =A34*0.5 | C34: =IF(B34<=Dados!$C$5,B34,2*Dados!$C$5-B34) | D34: =IF(C34<=Dados!$C$47,Dados!$C$44-Dados!$C$53*(C34-Dados!$C$52)^2,-Dados!$C$45+Dados!$C$54*(Dados!$C$5-C34)^2) | E34: =IF(B34<=Dados!$C$5,1,-1)*IF(C34<=Dados!$C$47,-2*Dados!$C$53*(C34-Dados!$C$52),-2*Dados!$C$54*(Dados!$C$5-C34)) | F34: =ATAN(E34) | G34: =COS(F34) | H34: =SIN(F34) | I34: =ABS(F34-F33) | J34: =J33+I34 | K34: =SQRT((B34-B33)^2+(D34-D33)^2) | L34: =L33+K34 | M34: =Dados!$C$67*EXP(-Dados!$C$70*J34-Dados!$C$71*L34) | N34: =N33+0.5*(M34+M33)*(B34-B33) | P34: =P22 | Q34: =MAX(Dados!$C$77*(Dados!$C$59*(1/Dados!$C$8+D34^2/Dados!$C$9)*P34-Esforcos!D34*D34/Dados!$C$9/1000)/(1+Dados!$C$77*Dados!$C$59*(1/Dados!$C$8+D34^2/Dados!$C$9)),0) | R34: =P34-Q34 | S34: =Dados!$C$59*R34*1000 | T34: =(-S34/Dados!$C$8-S34*D34^2/Dados!$C$9+Esforcos!D34*D34/Dados!$C$9)/1000 | U34: =R34/Dados!$C$60 | V34: =IF(U34<=0.5,0,IF(U34<=0.6,(U34-0.5)/0.1*1.3,IF(U34<=0.7,1.3+(U34-0.6)/0.1*1.2,IF(U34<=0.8,2.5+(U34-0.7)/0.1*1,3.5))))/100 | W34: =2.5*V34 | X34: =-LN(1-W34) | Y34: =1+D34^2*Dados!$C$8/Dados!$C$9 | Z34: =(ABS(Dados!$C$74)*Dados!$C$65+Dados!$C$76*ABS(T34)*Dados!$C$73+R34*X34)/((1+X34)+(1+0.5*Dados!$C$73)*Dados!$C$76*Y34*Dados!$C$78) | AA34: =R34-Z34 | AB34: =Dados!$C$59*AA34*1000 | AC34: =S34/Dados!$C$68 | AD34: =AB34/S34
A35: 27 | B35: =A35*0.5 | C35: =IF(B35<=Dados!$C$5,B35,2*Dados!$C$5-B35) | D35: =IF(C35<=Dados!$C$47,Dados!$C$44-Dados!$C$53*(C35-Dados!$C$52)^2,-Dados!$C$45+Dados!$C$54*(Dados!$C$5-C35)^2) | E35: =IF(B35<=Dados!$C$5,1,-1)*IF(C35<=Dados!$C$47,-2*Dados!$C$53*(C35-Dados!$C$52),-2*Dados!$C$54*(Dados!$C$5-C35)) | F35: =ATAN(E35) | G35: =COS(F35) | H35: =SIN(F35) | I35: =ABS(F35-F34) | J35: =J34+I35 | K35: =SQRT((B35-B34)^2+(D35-D34)^2) | L35: =L34+K35 | M35: =Dados!$C$67*EXP(-Dados!$C$70*J35-Dados!$C$71*L35) | N35: =N34+0.5*(M35+M34)*(B35-B34) | P35: =P21 | Q35: =MAX(Dados!$C$77*(Dados!$C$59*(1/Dados!$C$8+D35^2/Dados!$C$9)*P35-Esforcos!D35*D35/Dados!$C$9/1000)/(1+Dados!$C$77*Dados!$C$59*(1/Dados!$C$8+D35^2/Dados!$C$9)),0) | R35: =P35-Q35 | S35: =Dados!$C$59*R35*1000 | T35: =(-S35/Dados!$C$8-S35*D35^2/Dados!$C$9+Esforcos!D35*D35/Dados!$C$9)/1000 | U35: =R35/Dados!$C$60 | V35: =IF(U35<=0.5,0,IF(U35<=0.6,(U35-0.5)/0.1*1.3,IF(U35<=0.7,1.3+(U35-0.6)/0.1*1.2,IF(U35<=0.8,2.5+(U35-0.7)/0.1*1,3.5))))/100 | W35: =2.5*V35 | X35: =-LN(1-W35) | Y35: =1+D35^2*Dados!$C$8/Dados!$C$9 | Z35: =(ABS(Dados!$C$74)*Dados!$C$65+Dados!$C$76*ABS(T35)*Dados!$C$73+R35*X35)/((1+X35)+(1+0.5*Dados!$C$73)*Dados!$C$76*Y35*Dados!$C$78) | AA35: =R35-Z35 | AB35: =Dados!$C$59*AA35*1000 | AC35: =S35/Dados!$C$68 | AD35: =AB35/S35
A36: 28 | B36: =A36*0.5 | C36: =IF(B36<=Dados!$C$5,B36,2*Dados!$C$5-B36) | D36: =IF(C36<=Dados!$C$47,Dados!$C$44-Dados!$C$53*(C36-Dados!$C$52)^2,-Dados!$C$45+Dados!$C$54*(Dados!$C$5-C36)^2) | E36: =IF(B36<=Dados!$C$5,1,-1)*IF(C36<=Dados!$C$47,-2*Dados!$C$53*(C36-Dados!$C$52),-2*Dados!$C$54*(Dados!$C$5-C36)) | F36: =ATAN(E36) | G36: =COS(F36) | H36: =SIN(F36) | I36: =ABS(F36-F35) | J36: =J35+I36 | K36: =SQRT((B36-B35)^2+(D36-D35)^2) | L36: =L35+K36 | M36: =Dados!$C$67*EXP(-Dados!$C$70*J36-Dados!$C$71*L36) | N36: =N35+0.5*(M36+M35)*(B36-B35) | P36: =P20 | Q36: =MAX(Dados!$C$77*(Dados!$C$59*(1/Dados!$C$8+D36^2/Dados!$C$9)*P36-Esforcos!D36*D36/Dados!$C$9/1000)/(1+Dados!$C$77*Dados!$C$59*(1/Dados!$C$8+D36^2/Dados!$C$9)),0) | R36: =P36-Q36 | S36: =Dados!$C$59*R36*1000 | T36: =(-S36/Dados!$C$8-S36*D36^2/Dados!$C$9+Esforcos!D36*D36/Dados!$C$9)/1000 | U36: =R36/Dados!$C$60 | V36: =IF(U36<=0.5,0,IF(U36<=0.6,(U36-0.5)/0.1*1.3,IF(U36<=0.7,1.3+(U36-0.6)/0.1*1.2,IF(U36<=0.8,2.5+(U36-0.7)/0.1*1,3.5))))/100 | W36: =2.5*V36 | X36: =-LN(1-W36) | Y36: =1+D36^2*Dados!$C$8/Dados!$C$9 | Z36: =(ABS(Dados!$C$74)*Dados!$C$65+Dados!$C$76*ABS(T36)*Dados!$C$73+R36*X36)/((1+X36)+(1+0.5*Dados!$C$73)*Dados!$C$76*Y36*Dados!$C$78) | AA36: =R36-Z36 | AB36: =Dados!$C$59*AA36*1000 | AC36: =S36/Dados!$C$68 | AD36: =AB36/S36
A37: 29 | B37: =A37*0.5 | C37: =IF(B37<=Dados!$C$5,B37,2*Dados!$C$5-B37) | D37: =IF(C37<=Dados!$C$47,Dados!$C$44-Dados!$C$53*(C37-Dados!$C$52)^2,-Dados!$C$45+Dados!$C$54*(Dados!$C$5-C37)^2) | E37: =IF(B37<=Dados!$C$5,1,-1)*IF(C37<=Dados!$C$47,-2*Dados!$C$53*(C37-Dados!$C$52),-2*Dados!$C$54*(Dados!$C$5-C37)) | F37: =ATAN(E37) | G37: =COS(F37) | H37: =SIN(F37) | I37: =ABS(F37-F36) | J37: =J36+I37 | K37: =SQRT((B37-B36)^2+(D37-D36)^2) | L37: =L36+K37 | M37: =Dados!$C$67*EXP(-Dados!$C$70*J37-Dados!$C$71*L37) | N37: =N36+0.5*(M37+M36)*(B37-B36) | P37: =P19 | Q37: =MAX(Dados!$C$77*(Dados!$C$59*(1/Dados!$C$8+D37^2/Dados!$C$9)*P37-Esforcos!D37*D37/Dados!$C$9/1000)/(1+Dados!$C$77*Dados!$C$59*(1/Dados!$C$8+D37^2/Dados!$C$9)),0) | R37: =P37-Q37 | S37: =Dados!$C$59*R37*1000 | T37: =(-S37/Dados!$C$8-S37*D37^2/Dados!$C$9+Esforcos!D37*D37/Dados!$C$9)/1000 | U37: =R37/Dados!$C$60 | V37: =IF(U37<=0.5,0,IF(U37<=0.6,(U37-0.5)/0.1*1.3,IF(U37<=0.7,1.3+(U37-0.6)/0.1*1.2,IF(U37<=0.8,2.5+(U37-0.7)/0.1*1,3.5))))/100 | W37: =2.5*V37 | X37: =-LN(1-W37) | Y37: =1+D37^2*Dados!$C$8/Dados!$C$9 | Z37: =(ABS(Dados!$C$74)*Dados!$C$65+Dados!$C$76*ABS(T37)*Dados!$C$73+R37*X37)/((1+X37)+(1+0.5*Dados!$C$73)*Dados!$C$76*Y37*Dados!$C$78) | AA37: =R37-Z37 | AB37: =Dados!$C$59*AA37*1000 | AC37: =S37/Dados!$C$68 | AD37: =AB37/S37
A38: 30 | B38: =A38*0.5 | C38: =IF(B38<=Dados!$C$5,B38,2*Dados!$C$5-B38) | D38: =IF(C38<=Dados!$C$47,Dados!$C$44-Dados!$C$53*(C38-Dados!$C$52)^2,-Dados!$C$45+Dados!$C$54*(Dados!$C$5-C38)^2) | E38: =IF(B38<=Dados!$C$5,1,-1)*IF(C38<=Dados!$C$47,-2*Dados!$C$53*(C38-Dados!$C$52),-2*Dados!$C$54*(Dados!$C$5-C38)) | F38: =ATAN(E38) | G38: =COS(F38) | H38: =SIN(F38) | I38: =ABS(F38-F37) | J38: =J37+I38 | K38: =SQRT((B38-B37)^2+(D38-D37)^2) | L38: =L37+K38 | M38: =Dados!$C$67*EXP(-Dados!$C$70*J38-Dados!$C$71*L38) | N38: =N37+0.5*(M38+M37)*(B38-B37) | P38: =P18 | Q38: =MAX(Dados!$C$77*(Dados!$C$59*(1/Dados!$C$8+D38^2/Dados!$C$9)*P38-Esforcos!D38*D38/Dados!$C$9/1000)/(1+Dados!$C$77*Dados!$C$59*(1/Dados!$C$8+D38^2/Dados!$C$9)),0) | R38: =P38-Q38 | S38: =Dados!$C$59*R38*1000 | T38: =(-S38/Dados!$C$8-S38*D38^2/Dados!$C$9+Esforcos!D38*D38/Dados!$C$9)/1000 | U38: =R38/Dados!$C$60 | V38: =IF(U38<=0.5,0,IF(U38<=0.6,(U38-0.5)/0.1*1.3,IF(U38<=0.7,1.3+(U38-0.6)/0.1*1.2,IF(U38<=0.8,2.5+(U38-0.7)/0.1*1,3.5))))/100 | W38: =2.5*V38 | X38: =-LN(1-W38) | Y38: =1+D38^2*Dados!$C$8/Dados!$C$9 | Z38: =(ABS(Dados!$C$74)*Dados!$C$65+Dados!$C$76*ABS(T38)*Dados!$C$73+R38*X38)/((1+X38)+(1+0.5*Dados!$C$73)*Dados!$C$76*Y38*Dados!$C$78) | AA38: =R38-Z38 | AB38: =Dados!$C$59*AA38*1000 | AC38: =S38/Dados!$C$68 | AD38: =AB38/S38
A39: 31 | B39: =A39*0.5 | C39: =IF(B39<=Dados!$C$5,B39,2*Dados!$C$5-B39) | D39: =IF(C39<=Dados!$C$47,Dados!$C$44-Dados!$C$53*(C39-Dados!$C$52)^2,-Dados!$C$45+Dados!$C$54*(Dados!$C$5-C39)^2) | E39: =IF(B39<=Dados!$C$5,1,-1)*IF(C39<=Dados!$C$47,-2*Dados!$C$53*(C39-Dados!$C$52),-2*Dados!$C$54*(Dados!$C$5-C39)) | F39: =ATAN(E39) | G39: =COS(F39) | H39: =SIN(F39) | I39: =ABS(F39-F38) | J39: =J38+I39 | K39: =SQRT((B39-B38)^2+(D39-D38)^2) | L39: =L38+K39 | M39: =Dados!$C$67*EXP(-Dados!$C$70*J39-Dados!$C$71*L39) | N39: =N38+0.5*(M39+M38)*(B39-B38) | P39: =P17 | Q39: =MAX(Dados!$C$77*(Dados!$C$59*(1/Dados!$C$8+D39^2/Dados!$C$9)*P39-Esforcos!D39*D39/Dados!$C$9/1000)/(1+Dados!$C$77*Dados!$C$59*(1/Dados!$C$8+D39^2/Dados!$C$9)),0) | R39: =P39-Q39 | S39: =Dados!$C$59*R39*1000 | T39: =(-S39/Dados!$C$8-S39*D39^2/Dados!$C$9+Esforcos!D39*D39/Dados!$C$9)/1000 | U39: =R39/Dados!$C$60 | V39: =IF(U39<=0.5,0,IF(U39<=0.6,(U39-0.5)/0.1*1.3,IF(U39<=0.7,1.3+(U39-0.6)/0.1*1.2,IF(U39<=0.8,2.5+(U39-0.7)/0.1*1,3.5))))/100 | W39: =2.5*V39 | X39: =-LN(1-W39) | Y39: =1+D39^2*Dados!$C$8/Dados!$C$9 | Z39: =(ABS(Dados!$C$74)*Dados!$C$65+Dados!$C$76*ABS(T39)*Dados!$C$73+R39*X39)/((1+X39)+(1+0.5*Dados!$C$73)*Dados!$C$76*Y39*Dados!$C$78) | AA39: =R39-Z39 | AB39: =Dados!$C$59*AA39*1000 | AC39: =S39/Dados!$C$68 | AD39: =AB39/S39
A40: 32 | B40: =A40*0.5 | C40: =IF(B40<=Dados!$C$5,B40,2*Dados!$C$5-B40) | D40: =IF(C40<=Dados!$C$47,Dados!$C$44-Dados!$C$53*(C40-Dados!$C$52)^2,-Dados!$C$45+Dados!$C$54*(Dados!$C$5-C40)^2) | E40: =IF(B40<=Dados!$C$5,1,-1)*IF(C40<=Dados!$C$47,-2*Dados!$C$53*(C40-Dados!$C$52),-2*Dados!$C$54*(Dados!$C$5-C40)) | F40: =ATAN(E40) | G40: =COS(F40) | H40: =SIN(F40) | I40: =ABS(F40-F39) | J40: =J39+I40 | K40: =SQRT((B40-B39)^2+(D40-D39)^2) | L40: =L39+K40 | M40: =Dados!$C$67*EXP(-Dados!$C$70*J40-Dados!$C$71*L40) | N40: =N39+0.5*(M40+M39)*(B40-B39) | P40: =P16 | Q40: =MAX(Dados!$C$77*(Dados!$C$59*(1/Dados!$C$8+D40^2/Dados!$C$9)*P40-Esforcos!D40*D40/Dados!$C$9/1000)/(1+Dados!$C$77*Dados!$C$59*(1/Dados!$C$8+D40^2/Dados!$C$9)),0) | R40: =P40-Q40 | S40: =Dados!$C$59*R40*1000 | T40: =(-S40/Dados!$C$8-S40*D40^2/Dados!$C$9+Esforcos!D40*D40/Dados!$C$9)/1000 | U40: =R40/Dados!$C$60 | V40: =IF(U40<=0.5,0,IF(U40<=0.6,(U40-0.5)/0.1*1.3,IF(U40<=0.7,1.3+(U40-0.6)/0.1*1.2,IF(U40<=0.8,2.5+(U40-0.7)/0.1*1,3.5))))/100 | W40: =2.5*V40 | X40: =-LN(1-W40) | Y40: =1+D40^2*Dados!$C$8/Dados!$C$9 | Z40: =(ABS(Dados!$C$74)*Dados!$C$65+Dados!$C$76*ABS(T40)*Dados!$C$73+R40*X40)/((1+X40)+(1+0.5*Dados!$C$73)*Dados!$C$76*Y40*Dados!$C$78) | AA40: =R40-Z40 | AB40: =Dados!$C$59*AA40*1000 | AC40: =S40/Dados!$C$68 | AD40: =AB40/S40
A41: 33 | B41: =A41*0.5 | C41: =IF(B41<=Dados!$C$5,B41,2*Dados!$C$5-B41) | D41: =IF(C41<=Dados!$C$47,Dados!$C$44-Dados!$C$53*(C41-Dados!$C$52)^2,-Dados!$C$45+Dados!$C$54*(Dados!$C$5-C41)^2) | E41: =IF(B41<=Dados!$C$5,1,-1)*IF(C41<=Dados!$C$47,-2*Dados!$C$53*(C41-Dados!$C$52),-2*Dados!$C$54*(Dados!$C$5-C41)) | F41: =ATAN(E41) | G41: =COS(F41) | H41: =SIN(F41) | I41: =ABS(F41-F40) | J41: =J40+I41 | K41: =SQRT((B41-B40)^2+(D41-D40)^2) | L41: =L40+K41 | M41: =Dados!$C$67*EXP(-Dados!$C$70*J41-Dados!$C$71*L41) | N41: =N40+0.5*(M41+M40)*(B41-B40) | P41: =P15 | Q41: =MAX(Dados!$C$77*(Dados!$C$59*(1/Dados!$C$8+D41^2/Dados!$C$9)*P41-Esforcos!D41*D41/Dados!$C$9/1000)/(1+Dados!$C$77*Dados!$C$59*(1/Dados!$C$8+D41^2/Dados!$C$9)),0) | R41: =P41-Q41 | S41: =Dados!$C$59*R41*1000 | T41: =(-S41/Dados!$C$8-S41*D41^2/Dados!$C$9+Esforcos!D41*D41/Dados!$C$9)/1000 | U41: =R41/Dados!$C$60 | V41: =IF(U41<=0.5,0,IF(U41<=0.6,(U41-0.5)/0.1*1.3,IF(U41<=0.7,1.3+(U41-0.6)/0.1*1.2,IF(U41<=0.8,2.5+(U41-0.7)/0.1*1,3.5))))/100 | W41: =2.5*V41 | X41: =-LN(1-W41) | Y41: =1+D41^2*Dados!$C$8/Dados!$C$9 | Z41: =(ABS(Dados!$C$74)*Dados!$C$65+Dados!$C$76*ABS(T41)*Dados!$C$73+R41*X41)/((1+X41)+(1+0.5*Dados!$C$73)*Dados!$C$76*Y41*Dados!$C$78) | AA41: =R41-Z41 | AB41: =Dados!$C$59*AA41*1000 | AC41: =S41/Dados!$C$68 | AD41: =AB41/S41
A42: 34 | B42: =A42*0.5 | C42: =IF(B42<=Dados!$C$5,B42,2*Dados!$C$5-B42) | D42: =IF(C42<=Dados!$C$47,Dados!$C$44-Dados!$C$53*(C42-Dados!$C$52)^2,-Dados!$C$45+Dados!$C$54*(Dados!$C$5-C42)^2) | E42: =IF(B42<=Dados!$C$5,1,-1)*IF(C42<=Dados!$C$47,-2*Dados!$C$53*(C42-Dados!$C$52),-2*Dados!$C$54*(Dados!$C$5-C42)) | F42: =ATAN(E42) | G42: =COS(F42) | H42: =SIN(F42) | I42: =ABS(F42-F41) | J42: =J41+I42 | K42: =SQRT((B42-B41)^2+(D42-D41)^2) | L42: =L41+K42 | M42: =Dados!$C$67*EXP(-Dados!$C$70*J42-Dados!$C$71*L42) | N42: =N41+0.5*(M42+M41)*(B42-B41) | P42: =P14 | Q42: =MAX(Dados!$C$77*(Dados!$C$59*(1/Dados!$C$8+D42^2/Dados!$C$9)*P42-Esforcos!D42*D42/Dados!$C$9/1000)/(1+Dados!$C$77*Dados!$C$59*(1/Dados!$C$8+D42^2/Dados!$C$9)),0) | R42: =P42-Q42 | S42: =Dados!$C$59*R42*1000 | T42: =(-S42/Dados!$C$8-S42*D42^2/Dados!$C$9+Esforcos!D42*D42/Dados!$C$9)/1000 | U42: =R42/Dados!$C$60 | V42: =IF(U42<=0.5,0,IF(U42<=0.6,(U42-0.5)/0.1*1.3,IF(U42<=0.7,1.3+(U42-0.6)/0.1*1.2,IF(U42<=0.8,2.5+(U42-0.7)/0.1*1,3.5))))/100 | W42: =2.5*V42 | X42: =-LN(1-W42) | Y42: =1+D42^2*Dados!$C$8/Dados!$C$9 | Z42: =(ABS(Dados!$C$74)*Dados!$C$65+Dados!$C$76*ABS(T42)*Dados!$C$73+R42*X42)/((1+X42)+(1+0.5*Dados!$C$73)*Dados!$C$76*Y42*Dados!$C$78) | AA42: =R42-Z42 | AB42: =Dados!$C$59*AA42*1000 | AC42: =S42/Dados!$C$68 | AD42: =AB42/S42
A43: 35 | B43: =A43*0.5 | C43: =IF(B43<=Dados!$C$5,B43,2*Dados!$C$5-B43) | D43: =IF(C43<=Dados!$C$47,Dados!$C$44-Dados!$C$53*(C43-Dados!$C$52)^2,-Dados!$C$45+Dados!$C$54*(Dados!$C$5-C43)^2) | E43: =IF(B43<=Dados!$C$5,1,-1)*IF(C43<=Dados!$C$47,-2*Dados!$C$53*(C43-Dados!$C$52),-2*Dados!$C$54*(Dados!$C$5-C43)) | F43: =ATAN(E43) | G43: =COS(F43) | H43: =SIN(F43) | I43: =ABS(F43-F42) | J43: =J42+I43 | K43: =SQRT((B43-B42)^2+(D43-D42)^2) | L43: =L42+K43 | M43: =Dados!$C$67*EXP(-Dados!$C$70*J43-Dados!$C$71*L43) | N43: =N42+0.5*(M43+M42)*(B43-B42) | P43: =P13 | Q43: =MAX(Dados!$C$77*(Dados!$C$59*(1/Dados!$C$8+D43^2/Dados!$C$9)*P43-Esforcos!D43*D43/Dados!$C$9/1000)/(1+Dados!$C$77*Dados!$C$59*(1/Dados!$C$8+D43^2/Dados!$C$9)),0) | R43: =P43-Q43 | S43: =Dados!$C$59*R43*1000 | T43: =(-S43/Dados!$C$8-S43*D43^2/Dados!$C$9+Esforcos!D43*D43/Dados!$C$9)/1000 | U43: =R43/Dados!$C$60 | V43: =IF(U43<=0.5,0,IF(U43<=0.6,(U43-0.5)/0.1*1.3,IF(U43<=0.7,1.3+(U43-0.6)/0.1*1.2,IF(U43<=0.8,2.5+(U43-0.7)/0.1*1,3.5))))/100 | W43: =2.5*V43 | X43: =-LN(1-W43) | Y43: =1+D43^2*Dados!$C$8/Dados!$C$9 | Z43: =(ABS(Dados!$C$74)*Dados!$C$65+Dados!$C$76*ABS(T43)*Dados!$C$73+R43*X43)/((1+X43)+(1+0.5*Dados!$C$73)*Dados!$C$76*Y43*Dados!$C$78) | AA43: =R43-Z43 | AB43: =Dados!$C$59*AA43*1000 | AC43: =S43/Dados!$C$68 | AD43: =AB43/S43
